Workbook

Sheet Início
A1: PLANILHA DE CONTROLE E PRESCRIÇÃO DE TREINAMENTO • VOLEIBOL
A2: Periodização Macrociclo → Mesociclo → Microciclo → Sessão | Controle de carga por PSE da sessão, ACWR, Monotonia/Strain e Wellness
B4: COMO USAR — PASSO A PASSO
B5: 1. Listas | C5: Opções de todos os menus suspensos (posições, escolaridade, renda, tipos de sessão, superfícies…).
B6: 2. Cadastro | C6: Ficha completa do atleta: identificação, contato, SOCIOECONÔMICO, histórico esportivo e saúde.
B7: 3. Antropometria | C7: Avaliações longitudinais no perfil ISAK: dobras, perímetros, diâmetros, % de gordura e somatotipo.
B8: 4. Testes | C8: Bateria física: alcances e impulsões, SJ, CMJ, drop jump com RSI, sprint, agilidade e IMTP.
B9: 5. Perfil F-V-P | C9: Perfil força-velocidade-potência pelo salto com carga: F0, V0, Pmax e desequilíbrio F-V.
B10: 6. Exercícios | C10: Biblioteca com 89 exercícios, incluindo todos os do seu documento de Preparação Física.
B11: 7. Programa PF | C11: As 8 séries do seu documento 'Preparação Física 2026/2027', na íntegra.
B12: 8. Macrociclo | C12: A temporada dividida em mesociclos, com dinâmica de volume e intensidade.
B13: 9. Mesociclo | C13: Microciclos do mesociclo escolhido, com carga prevista × realizada.
B14: 10. Bloco Base | C14: PERIODIZAÇÃO EM BLOCOS: as 8 semanas de base (força máxima, LPO, agachamento e pliometria).
B15: 11. Microciclo | C15: A semana de quadra: sessões por dia e distribuição de conteúdos.
B16: 12. Prescrição | C16: Prescrição do treino técnico-tático, por equipe ou por atleta.
... B26: 22. Evidências | C26: 60 referências científicas que sustentam cada escolha metodológica da planilha.
B28: LEGENDA DE CORES
B29: Célula de PREENCHIMENTO (azul sobre amarelo)
B30: Célula CALCULADA — não digite por cima
B31: Cabeçalho de tabela
B32: Alerta / risco elevado
B33: Atenção / monitorar
B34: Adequado / dentro da meta
B36: MÉTRICAS DE CONTROLE UTILIZADAS — DEFINIÇÕES E REFERÊNCIAS
B37: Carga Interna (UA) | C37: Duração da sessão (min) × PSE da sessão (escala 0–10, coletada ~30 min após o treino). Método da PSE da sessão de Foster et al. (2001), J Strength Cond Res.
B38: Carga Aguda (7 d) | C38: Soma da carga em UA dos últimos 7 dias do atleta (inclui o dia atual).
B39: Carga Crônica (28 d) | C39: Soma da carga dos últimos 28 dias ÷ 4 (média semanal), para ficar na mesma escala da aguda.
B40: ACWR | C40: Carga Aguda ÷ Carga Crônica. Faixas usadas na planilha: <0,80 subcarga | 0,80–1,30 zona ideal | 1,31–1,50 atenção | >1,50 risco elevado. Referência: Gabbett (2016), Br J Sports Med. Interpretar sempre junto do contexto e da clínica do atleta.
B41: Monotonia | C41: Média das cargas diárias da semana ÷ desvio-padrão dessas mesmas cargas (7 dias, dias de folga contam como zero). >2,0 indica semana monótona.
B42: Strain | C42: Carga semanal total × Monotonia. Picos de strain associam-se a maior risco de lesão/doença (Foster, 1998).
B43: Índice de Hooper | C43: Soma de 4 itens (qualidade do sono, estresse, fadiga e dor muscular), cada um de 1 = muito bom/ausente a 7 = muito ruim/máxima. Varia de 4 a 28; QUANTO MAIOR, PIOR. Referência: Hooper & Mackinnon (1995), Sports Med.
B44: Volume × Intensidade | C44: No Macrociclo, valores em % representam a proporção relativa planejada para cada mesociclo (ex.: 85% = volume alto).
B45: Tonelagem | C45: Séries × repetições × carga usada, em kg. É o volume-carga do treino de força; some por sessão, semana e bloco.
B46: Intensidade média relativa | C46: Média dos %1RM prescritos, ponderada pelo número de repetições de cada exercício. Mostra o quanto a semana foi 'pesada' de verdade.
B47: Perda de velocidade | C47: Queda percentual da velocidade da barra dentro da série. Limiares ≤ 25% favorecem força; acima de 20–25% favorecem hipertrofia (Hickmott et al., 2022).
B48: F0, V0 e Pmax | C48: Força teórica máxima, velocidade teórica máxima e potência máxima estimadas por regressão linear a partir de saltos com cargas progressivas (Morin & Samozino, 2016).
... B52: Somatotipo | C52: Endomorfia, mesomorfia e ectomorfia pelo método Heath-Carter, a partir de dobras, perímetros, diâmetros, estatura e massa.
B54: ATENÇÃO — DADOS DE EXEMPLO: a planilha vem preenchida com 12 atletas fictícios, um macrociclo modelo e registros de carga/wellness/presença apenas para demonstrar os cálculos e os gráficos. Apague esses dados (linhas marcadas como EXEMPLO) antes de usar com a sua equipe. As fórmulas permanecem intactas. AVISO: esta planilha é uma ferramenta de organização do treino. Não substitui avaliação médica nem fisioterápica; os indicadores de risco são apoio à decisão do técnico/preparador físico.

Sheet Cadastro
A1: CADASTRO DE ATLETAS — FICHA COMPLETA
A2: Uma linha por atleta. Blocos: Identificação · Antropometria (puxada da aba Antropometria) · Contato · Socioeconômico · Histórico Esportivo · Saúde · Situação.
B4: LGPD — esta aba armazena dados pessoais e de saúde (dados sensíveis). Colete somente o necessário, com consentimento por escrito do atleta (ou do responsável, se menor), e restrinja o acesso ao arquivo. Por decisão do usuário, NENHUM dado financeiro do atleta é registrado aqui.
A6: IDENTIFICAÇÃO | M6: ANTROPOMETRIA (puxada da aba Antropometria) | R6: CONTATO | Z6: SOCIOECONÔMICO | AS6: HISTÓRICO ESPORTIVO | AY6: SAÚDE | BK6: SITUAÇÃO
A7: ID | B7: Nome Completo | C7: Nome na Equipe | D7: Data de Nasc. | E7: Idade | F7: Sexo | G7: Nacionalidade | H7: Naturalidade (Cidade/UF) | I7: Documento (RG/CPF) | J7: Nº Camisa | K7: Categoria | L7: Posição | M7: Dominância de Mão | N7: Perna de Impulsão | O7: Estatura (cm) | P7: Massa (kg) | Q7: IMC | R7: Telefone | S7: E-mail | T7: Endereço | U7: Cidade / UF | V7: CEP | W7: Contato de Emergência | X7: Telefone de Emergência | Y7: Parentesco | Z7: Escolaridade | AA7: Situação de Estudo | AB7: Turno de Estudo | AC7: Instituição de Ensino | AD7: Trabalha? | AE7: Horas de Trabalho / Semana | AF7: Ocupação | AG7: Nº de Pessoas no Domicílio | AH7: Classe Econômica (Critério Brasil) | AI7: Tipo de Moradia | AJ7: Reside com | AK7: Transporte para o Treino | AL7: Tempo de Deslocamento (min) | AM7: Recebe Bolsa / Auxílio? | AN7: Benefício Social | AO7: Plano de Saúde | AP7: Acesso à Internet em Casa | AQ7: Refeições por Dia | AR7: Acompanhamento Nutricional | AS7: Idade de Início no Vôlei | AT7: Anos de Prática | AU7: Anos de Treino de Força | AV7: Nível Competitivo Máximo | AW7: Clubes Anteriores | AX7: Seleções / Convocações | AY7: Tipo Sanguíneo | AZ7: Alergias | BA7: Medicamentos em Uso | BB7: Cirurgias Prévias | BC7: Lesões Prévias (região) | BD7: Nº de Lesões (12 meses) | BE7: Queixa / Dor Atual | BF7: Data do Atestado Médico | BG7: Validade do Atestado | BH7: Situação do Atestado | BI7: PAR-Q Respondido? | BJ7: Usa Óculos / Lentes? | BK7: Data de Entrada na Equipe | BL7: Status | BM7: Observações | BN7: últ. aval.
A8: =IF($B8="","","ATL-"&TEXT(ROW()-7,"000")) -> ATL-001 | B8: Rafael Monteiro Alves | C8: Rafa | D8: 35868 | E8: =IFERROR(DATEDIF($D8,TODAY(),"Y"),"") -> 28 | F8: Masculino | G8: Brasileira | H8: — | I8: — | J8: 5 | K8: Adulto | L8: Levantador | M8: Destro | N8: Esquerda | O8: =IF(OR($B8="",$BN8=0),"",IFERROR(AVERAGEIFS(Antropometria!$F$8:$F$407,Antropometria!$B$8:$B$407,$B8,Antropometria!$A$8:$A$407,$BN8),"")) -> 196 | P8: =IF(OR($B8="",$BN8=0),"",IFERROR(AVERAGEIFS(Antropometria!$E$8:$E$407,Antropometria!$B$8:$B$407,$B8,Antropometria!$A$8:$A$407,$BN8),"")) -> 87.8 | Q8: =IFERROR(ROUND($P8/($O8/100)^2,1),"") -> 22.9 | R8: (00) 90000-0001 | S8: atleta1@elase.com.br | T8: — | U8: — | V8: — | W8: Responsável / familiar | X8: (00) 90000-1001 | Y8: — | Z8: Superior em andamento | AA8: Cursando | AB8: Noturno | AC8: — | AD8: Não | AE8: 0 | AF8: Atleta profissional | AG8: 3 | AH8: B1 | AI8: Própria | AJ8: Família | AK8: Carro próprio | AL8: 25 | AM8: Sim | AN8: Não | AO8: Sim | AP8: Sim | AQ8: 6 | AR8: Sim | AS8: 11 | AT8: =IFERROR($E8-$AS8,"") -> 17 | AU8: 4 | AV8: Superliga A | AW8: — | AX8: Seleção estadual | AY8: O+ | AZ8: — | BA8: — | BB8: — | BC8: — | BD8: 0 | BE8: — | BF8: 46034 | BG8: 46399 | BH8: =IF($BG8="","",IF($BG8<TODAY(),"VENCIDO",IF($BG8<=TODAY()+30,"Vence em 30 dias","Válido"))) -> Válido | BI8: Sim | BJ8: Sim | BK8: 46027 | BL8: Ativo | BM8: EXEMPLO — substituir | BN8: =IF($B8="",0,IFERROR(SUMPRODUCT(MAX((Antropometria!$B$8:$B$407=$B8)*Antropometria!$A$8:$A$407)),0)) -> 46225
A9: =IF($B9="","","ATL-"&TEXT(ROW()-7,"000")) -> ATL-002 | B9: Diego Salgado Ferraz | C9: Diego | D9: 35279 | E9: =IFERROR(DATEDIF($D9,TODAY(),"Y"),"") -> 30 | F9: Masculino | G9: Brasileira | H9: — | I9: — | J9: 12 | K9: Adulto | L9: Oposto | M9: Canhoto | N9: Esquerda | O9: =IF(OR($B9="",$BN9=0),"",IFERROR(AVERAGEIFS(Antropometria!$F$8:$F$407,Antropometria!$B$8:$B$407,$B9,Antropometria!$A$8:$A$407,$BN9),"")) -> 202 | P9: =IF(OR($B9="",$BN9=0),"",IFERROR(AVERAGEIFS(Antropometria!$E$8:$E$407,Antropometria!$B$8:$B$407,$B9,Antropometria!$A$8:$A$407,$BN9),"")) -> 94.2 | Q9: =IFERROR(ROUND($P9/($O9/100)^2,1),"") -> 23.1 | R9: (00) 90000-0002 | S9: atleta2@elase.com.br | T9: — | U9: — | V9: — | W9: Responsável / familiar | X9: (00) 90000-1002 | Y9: — | Z9: Superior completo | AA9: Concluído | AB9: — | AC9: — | AD9: Não | AE9: 0 | AF9: Atleta profissional | AG9: 2 | AH9: B1 | AI9: Alugada | AJ9: Cônjuge | AK9: Carro próprio | AL9: 20 | AM9: Sim | AN9: Não | AO9: Sim | AP9: Sim | AQ9: 6 | AR9: Sim | AS9: 12 | AT9: =IFERROR($E9-$AS9,"") -> 18 | AU9: 6 | AV9: Superliga B | AW9: — | AX9: Seleção nacional Sub-21 | AY9: O+ | AZ9: — | BA9: — | BB9: — | BC9: Entorse de tornozelo D | BD9: 1 | BE9: — | BF9: 46034 | BG9: 46399 | BH9: =IF($BG9="","",IF($BG9<TODAY(),"VENCIDO",IF($BG9<=TODAY()+30,"Vence em 30 dias","Válido"))) -> Válido | BI9: Sim | BJ9: Não | BK9: 46027 | BL9: Ativo | BM9: EXEMPLO — substituir | BN9: =IF($B9="",0,IFERROR(SUMPRODUCT(MAX((Antropometria!$B$8:$B$407=$B9)*Antropometria!$A$8:$A$407)),0)) -> 46225
A10: =IF($B10="","","ATL-"&TEXT(ROW()-7,"000")) -> ATL-003 | B10: Lucas Prado Bittencourt | C10: Lucas | D10: 36552 | E10: =IFERROR(DATEDIF($D10,TODAY(),"Y"),"") -> 26 | F10: Masculino | G10: Brasileira | H10: — | I10: — | J10: 7 | K10: Adulto | L10: Ponteiro (Ponta) | M10: Destro | N10: Esquerda | O10: =IF(OR($B10="",$BN10=0),"",IFERROR(AVERAGEIFS(Antropometria!$F$8:$F$407,Antropometria!$B$8:$B$407,$B10,Antropometria!$A$8:$A$407,$BN10),"")) -> 198 | P10: =IF(OR($B10="",$BN10=0),"",IFERROR(AVERAGEIFS(Antropometria!$E$8:$E$407,Antropometria!$B$8:$B$407,$B10,Antropometria!$A$8:$A$407,$BN10),"")) -> 88.9 | Q10: =IFERROR(ROUND($P10/($O10/100)^2,1),"") -> 22.7 | R10: (00) 90000-0003 | S10: atleta3@elase.com.br | T10: — | U10: — | V10: — | W10: Responsável / familiar | X10: (00) 90000-1003 | Y10: — | Z10: Superior em andamento | AA10: Cursando | AB10: Matutino | AC10: — | AD10: Não | AE10: 0 | AF10: Atleta profissional | AG10: 4 | AH10: B2 | AI10: Própria | AJ10: Família | AK10: Transporte do clube | AL10: 35 | AM10: Sim | AN10: Não | AO10: Sim | AP10: Sim | AQ10: 5 | AR10: Sim | AS10: 13 | AT10: =IFERROR($E10-$AS10,"") -> 13 | AU10: 3 | AV10: Superliga B | AW10: — | AX10: Seleção estadual | AY10: O+ | AZ10: — | BA10: — | BB10: — | BC10: — | BD10: 0 | BE10: — | BF10: 46034 | BG10: 46399 | BH10: =IF($BG10="","",IF($BG10<TODAY(),"VENCIDO",IF($BG10<=TODAY()+30,"Vence em 30 dias","Válido"))) -> Válido | BI10: Sim | BJ10: Não | BK10: 46027 | BL10: Ativo | BM10: EXEMPLO — substituir | BN10: =IF($B10="",0,IFERROR(SUMPRODUCT(MAX((Antropometria!$B$8:$B$407=$B10)*Antropometria!$A$8:$A$407)),0)) -> 46225
A11: =IF($B11="","","ATL-"&TEXT(ROW()-7,"000")) -> ATL-004 | B11: Bruno Rezende Camargo | C11: Bruninho | D11: 36469 | E11: =IFERROR(DATEDIF($D11,TODAY(),"Y"),"") -> 26 | F11: Masculino | G11: Brasileira | H11: — | I11: — | J11: 9 | K11: Adulto | L11: Ponteiro (Ponta) | M11: Destro | N11: Esquerda | O11: =IF(OR($B11="",$BN11=0),"",IFERROR(AVERAGEIFS(Antropometria!$F$8:$F$407,Antropometria!$B$8:$B$407,$B11,Antropometria!$A$8:$A$407,$BN11),"")) -> 197 | P11: =IF(OR($B11="",$BN11=0),"",IFERROR(AVERAGEIFS(Antropometria!$E$8:$E$407,Antropometria!$B$8:$B$407,$B11,Antropometria!$A$8:$A$407,$BN11),"")) -> 87.7 | Q11: =IFERROR(ROUND($P11/($O11/100)^2,1),"") -> 22.6 | R11: (00) 90000-0004 | S11: atleta4@elase.com.br | T11: — | U11: — | V11: — | W11: Responsável / familiar | X11: (00) 90000-1004 | Y11: — | Z11: Superior em andamento | AA11: Cursando | AB11: Noturno | AC11: — | AD11: Sim | AE11: 20 | AF11: Estagiário | AG11: 4 | AH11: C1 | AI11: Alugada | AJ11: Família | AK11: Transporte público | AL11: 55 | AM11: Sim | AN11: Sim | AO11: Não | AP11: Sim | AQ11: 4 | AR11: Não | AS11: 12 | AT11: =IFERROR($E11-$AS11,"") -> 14 | AU11: 3 | AV11: Superliga A | AW11: — | AX11: — | AY11: O+ | AZ11: — | BA11: — | BB11: — | BC11: Tendinopatia patelar | BD11: 2 | BE11: Dor anterior no joelho D (leve) | BF11: 46034 | BG11: 46399 | BH11: =IF($BG11="","",IF($BG11<TODAY(),"VENCIDO",IF($BG11<=TODAY()+30,"Vence em 30 dias","Válido"))) -> Válido | BI11: Sim | BJ11: Não | BK11: 46027 | BL11: Lesionado | BM11: EXEMPLO — substituir | BN11: =IF($B11="",0,IFERROR(SUMPRODUCT(MAX((Antropometria!$B$8:$B$407=$B11)*Antropometria!$A$8:$A$407)),0)) -> 46225
A12: =IF($B12="","","ATL-"&TEXT(ROW()-7,"000")) -> ATL-005 | B12: Thiago Nogueira Vasques | C12: Thiago | D12: 34838 | E12: =IFERROR(DATEDIF($D12,TODAY(),"Y"),"") -> 31 | F12: Masculino | G12: Brasileira | H12: — | I12: — | J12: 4 | K12: Adulto | L12: Central | M12: Destro | N12: Direita | O12: =IF(OR($B12="",$BN12=0),"",IFERROR(AVERAGEIFS(Antropometria!$F$8:$F$407,Antropometria!$B$8:$B$407,$B12,Antropometria!$A$8:$A$407,$BN12),"")) -> 205 | P12: =IF(OR($B12="",$BN12=0),"",IFERROR(AVERAGEIFS(Antropometria!$E$8:$E$407,Antropometria!$B$8:$B$407,$B12,Antropometria!$A$8:$A$407,$BN12),"")) -> 99.7 | Q12: =IFERROR(ROUND($P12/($O12/100)^2,1),"") -> 23.7 | R12: (00) 90000-0005 | S12: atleta5@elase.com.br | T12: — | U12: — | V12: — | W12: Responsável / familiar | X12: (00) 90000-1005 | Y12: — | Z12: Superior completo | AA12: Concluído | AB12: — | AC12: — | AD12: Não | AE12: 0 | AF12: Atleta profissional | AG12: 3 | AH12: A | AI12: Própria | AJ12: Família | AK12: Carro próprio | AL12: 18 | AM12: Sim | AN12: Não | AO12: Sim | AP12: Sim | AQ12: 6 | AR12: Sim | AS12: 10 | AT12: =IFERROR($E12-$AS12,"") -> 21 | AU12: 8 | AV12: Superliga B | AW12: — | AX12: Seleção nacional adulta | AY12: O+ | AZ12: — | BA12: — | BB12: — | BC12: Lombalgia | BD12: 1 | BE12: — | BF12: 46034 | BG12: 46399 | BH12: =IF($BG12="","",IF($BG12<TODAY(),"VENCIDO",IF($BG12<=TODAY()+30,"Vence em 30 dias","Válido"))) -> Válido | BI12: Sim | BJ12: Sim | BK12: 46027 | BL12: Ativo | BM12: EXEMPLO — substituir | BN12: =IF($B12="",0,IFERROR(SUMPRODUCT(MAX((Antropometria!$B$8:$B$407=$B12)*Antropometria!$A$8:$A$407)),0)) -> 46225
A13: =IF($B13="","","ATL-"&TEXT(ROW()-7,"000")) -> ATL-006 | B13: Matheus Caldeira Lins | C13: Matheus | D13: 37142 | E13: =IFERROR(DATEDIF($D13,TODAY(),"Y"),"") -> 24 | F13: Masculino | G13: Brasileira | H13: — | I13: — | J13: 15 | K13: Adulto | L13: Central | M13: Destro | N13: Esquerda | O13: =IF(OR($B13="",$BN13=0),"",IFERROR(AVERAGEIFS(Antropometria!$F$8:$F$407,Antropometria!$B$8:$B$407,$B13,Antropometria!$A$8:$A$407,$BN13),"")) -> 203 | P13: =IF(OR($B13="",$BN13=0),"",IFERROR(AVERAGEIFS(Antropometria!$E$8:$E$407,Antropometria!$B$8:$B$407,$B13,Antropometria!$A$8:$A$407,$BN13),"")) -> 94.9 | Q13: =IFERROR(ROUND($P13/($O13/100)^2,1),"") -> 23 | R13: (00) 90000-0006 | S13: atleta6@elase.com.br | T13: — | U13: — | V13: — | W13: Responsável / familiar | X13: (00) 90000-1006 | Y13: — | Z13: Superior em andamento | AA13: Cursando | AB13: Noturno | AC13: — | AD13: Não | AE13: 0 | AF13: Atleta profissional | AG13: 5 | AH13: C1 | AI13: Cedida | AJ13: Alojamento do clube | AK13: A pé | AL13: 10 | AM13: Sim | AN13: Sim | AO13: Sim | AP13: Sim | AQ13: 5 | AR13: Sim | AS13: 14 | AT13: =IFERROR($E13-$AS13,"") -> 10 | AU13: 2 | AV13: Superliga B | AW13: — | AX13: — | AY13: O+ | AZ13: — | BA13: — | BB13: — | BC13: — | BD13: 0 | BE13: — | BF13: 46034 | BG13: 46399 | BH13: =IF($BG13="","",IF($BG13<TODAY(),"VENCIDO",IF($BG13<=TODAY()+30,"Vence em 30 dias","Válido"))) -> Válido | BI13: Sim | BJ13: Não | BK13: 46027 | BL13: Ativo | BM13: EXEMPLO — substituir | BN13: =IF($B13="",0,IFERROR(SUMPRODUCT(MAX((Antropometria!$B$8:$B$407=$B13)*Antropometria!$A$8:$A$407)),0)) -> 46225
A14: =IF($B14="","","ATL-"&TEXT(ROW()-7,"000")) -> ATL-007 | B14: Felipe Andrade Rocha | C14: Felipão | D14: 37663 | E14: =IFERROR(DATEDIF($D14,TODAY(),"Y"),"") -> 23 | F14: Masculino | G14: Brasileira | H14: — | I14: — | J14: 2 | K14: Adulto | L14: Líbero | M14: Destro | N14: Direita | O14: =IF(OR($B14="",$BN14=0),"",IFERROR(AVERAGEIFS(Antropometria!$F$8:$F$407,Antropometria!$B$8:$B$407,$B14,Antropometria!$A$8:$A$407,$BN14),"")) -> 184 | P14: =IF(OR($B14="",$BN14=0),"",IFERROR(AVERAGEIFS(Antropometria!$E$8:$E$407,Antropometria!$B$8:$B$407,$B14,Antropometria!$A$8:$A$407,$BN14),"")) -> 79 | Q14: =IFERROR(ROUND($P14/($O14/100)^2,1),"") -> 23.3 | R14: (00) 90000-0007 | S14: atleta7@elase.com.br | T14: — | U14: — | V14: — | W14: Responsável / familiar | X14: (00) 90000-1007 | Y14: — | Z14: Superior em andamento | AA14: Cursando | AB14: Matutino | AC14: — | AD14: Não | AE14: 0 | AF14: Atleta profissional | AG14: 4 | AH14: C2 | AI14: Alugada | AJ14: Alojamento do clube | AK14: Transporte do clube | AL14: 30 | AM14: Sim | AN14: Sim | AO14: Não | AP14: Sim | AQ14: 5 | AR14: Sim | AS14: 12 | AT14: =IFERROR($E14-$AS14,"") -> 11 | AU14: 2 | AV14: Superliga A | AW14: — | AX14: Seleção estadual Sub-19 | AY14: O+ | AZ14: — | BA14: — | BB14: — | BC14: Entorse de tornozelo E | BD14: 1 | BE14: — | BF14: 46034 | BG14: 46399 | BH14: =IF($BG14="","",IF($BG14<TODAY(),"VENCIDO",IF($BG14<=TODAY()+30,"Vence em 30 dias","Válido"))) -> Válido | BI14: Sim | BJ14: Não | BK14: 46027 | BL14: Ativo | BM14: EXEMPLO — substituir | BN14: =IF($B14="",0,IFERROR(SUMPRODUCT(MAX((Antropometria!$B$8:$B$407=$B14)*Antropometria!$A$8:$A$407)),0)) -> 46225
A15: =IF($B15="","","ATL-"&TEXT(ROW()-7,"000")) -> ATL-008 | B15: Gustavo Peixoto Maia | C15: Gu | D15: 35634 | E15: =IFERROR(DATEDIF($D15,TODAY(),"Y"),"") -> 29 | F15: Masculino | G15: Brasileira | H15: — | I15: — | J15: 11 | K15: Adulto | L15: Ponteiro (Ponta) | M15: Destro | N15: Esquerda | O15: =IF(OR($B15="",$BN15=0),"",IFERROR(AVERAGEIFS(Antropometria!$F$8:$F$407,Antropometria!$B$8:$B$407,$B15,Antropometria!$A$8:$A$407,$BN15),"")) -> 199 | P15: =IF(OR($B15="",$BN15=0),"",IFERROR(AVERAGEIFS(Antropometria!$E$8:$E$407,Antropometria!$B$8:$B$407,$B15,Antropometria!$A$8:$A$407,$BN15),"")) -> 90.4 | Q15: =IFERROR(ROUND($P15/($O15/100)^2,1),"") -> 22.8 | R15: (00) 90000-0008 | S15: atleta8@elase.com.br | T15: — | U15: — | V15: — | W15: Responsável / familiar | X15: (00) 90000-1008 | Y15: — | Z15: Superior completo | AA15: Concluído | AB15: — | AC15: — | AD15: Não | AE15: 0 | AF15: Atleta profissional | AG15: 2 | AH15: B1 | AI15: Própria | AJ15: Cônjuge | AK15: Carro próprio | AL15: 22 | AM15: Sim | AN15: Não | AO15: Sim | AP15: Sim | AQ15: 6 | AR15: Sim | AS15: 11 | AT15: =IFERROR($E15-$AS15,"") -> 18 | AU15: 7 | AV15: Superliga B | AW15: — | AX15: — | AY15: O+ | AZ15: — | BA15: — | BB15: — | BC15: Tendinopatia de ombro D | BD15: 1 | BE15: — | BF15: 46034 | BG15: 46399 | BH15: =IF($BG15="","",IF($BG15<TODAY(),"VENCIDO",IF($BG15<=TODAY()+30,"Vence em 30 dias","Válido"))) -> Válido | BI15: Sim | BJ15: Não | BK15: 46027 | BL15: Ativo | BM15: EXEMPLO — substituir | BN15: =IF($B15="",0,IFERROR(SUMPRODUCT(MAX((Antropometria!$B$8:$B$407=$B15)*Antropometria!$A$8:$A$407)),0)) -> 46225
A16: =IF($B16="","","ATL-"&TEXT(ROW()-7,"000")) -> ATL-009 | B16: Vinícius Barreto Duarte | C16: Vini | D16: 37593 | E16: =IFERROR(DATEDIF($D16,TODAY(),"Y"),"") -> 23 | F16: Masculino | G16: Brasileira | H16: — | I16: — | J16: 6 | K16: Adulto | L16: Levantador | M16: Destro | N16: Esquerda | O16: =IF(OR($B16="",$BN16=0),"",IFERROR(AVERAGEIFS(Antropometria!$F$8:$F$407,Antropometria!$B$8:$B$407,$B16,Antropometria!$A$8:$A$407,$BN16),"")) -> 192 | P16: =IF(OR($B16="",$BN16=0),"",IFERROR(AVERAGEIFS(Antropometria!$E$8:$E$407,Antropometria!$B$8:$B$407,$B16,Antropometria!$A$8:$A$407,$BN16),"")) -> 82.5 | Q16: =IFERROR(ROUND($P16/($O16/100)^2,1),"") -> 22.4 | R16: (00) 90000-0009 | S16: atleta9@elase.com.br | T16: — | U16: — | V16: — | W16: Responsável / familiar | X16: (00) 90000-1009 | Y16: — | Z16: Superior em andamento | AA16: Cursando | AB16: Noturno | AC16: — | AD16: Não | AE16: 0 | AF16: Atleta profissional | AG16: 5 | AH16: C2 | AI16: Cedida | AJ16: Alojamento do clube | AK16: A pé | AL16: 8 | AM16: Sim | AN16: Sim | AO16: Não | AP16: Sim | AQ16: 5 | AR16: Sim | AS16: 13 | AT16: =IFERROR($E16-$AS16,"") -> 10 | AU16: 2 | AV16: Superliga B | AW16: — | AX16: — | AY16: O+ | AZ16: — | BA16: — | BB16: — | BC16: — | BD16: 0 | BE16: — | BF16: 46034 | BG16: 46399 | BH16: =IF($BG16="","",IF($BG16<TODAY(),"VENCIDO",IF($BG16<=TODAY()+30,"Vence em 30 dias","Válido"))) -> Válido | BI16: Sim | BJ16: Sim | BK16: 46027 | BL16: Ativo | BM16: EXEMPLO — substituir | BN16: =IF($B16="",0,IFERROR(SUMPRODUCT(MAX((Antropometria!$B$8:$B$407=$B16)*Antropometria!$A$8:$A$407)),0)) -> 46225
A17: =IF($B17="","","ATL-"&TEXT(ROW()-7,"000")) -> ATL-010 | B17: André Luiz Sampaio | C17: Dedé | D17: 34454 | E17: =IFERROR(DATEDIF($D17,TODAY(),"Y"),"") -> 32 | F17: Masculino | G17: Brasileira | H17: — | I17: — | J17: 18 | K17: Adulto | L17: Oposto | M17: Destro | N17: Esquerda | O17: =IF(OR($B17="",$BN17=0),"",IFERROR(AVERAGEIFS(Antropometria!$F$8:$F$407,Antropometria!$B$8:$B$407,$B17,Antropometria!$A$8:$A$407,$BN17),"")) -> 201 | P17: =IF(OR($B17="",$BN17=0),"",IFERROR(AVERAGEIFS(Antropometria!$E$8:$E$407,Antropometria!$B$8:$B$407,$B17,Antropometria!$A$8:$A$407,$BN17),"")) -> 97.5 | Q17: =IFERROR(ROUND($P17/($O17/100)^2,1),"") -> 24.1 | R17: (00) 90000-0010 | S17: atleta10@elase.com.br | T17: — | U17: — | V17: — | W17: Responsável / familiar | X17: (00) 90000-1010 | Y17: — | Z17: Superior completo | AA17: Concluído | AB17: — | AC17: — | AD17: Não | AE17: 0 | AF17: Atleta profissional | AG17: 4 | AH17: A | AI17: Própria | AJ17: Família | AK17: Carro próprio | AL17: 15 | AM17: Sim | AN17: Não | AO17: Sim | AP17: Sim | AQ17: 6 | AR17: Sim | AS17: 10 | AT17: =IFERROR($E17-$AS17,"") -> 22 | AU17: 9 | AV17: Superliga A | AW17: — | AX17: Seleção nacional adulta | AY17: O+ | AZ17: — | BA17: — | BB17: Cirurgia de ombro D (2021) | BC17: Cirurgia de ombro D (2021) | BD17: 0 | BE17: — | BF17: 46034 | BG17: 46399 | BH17: =IF($BG17="","",IF($BG17<TODAY(),"VENCIDO",IF($BG17<=TODAY()+30,"Vence em 30 dias","Válido"))) -> Válido | BI17: Sim | BJ17: Não | BK17: 46027 | BL17: Ativo | BM17: EXEMPLO — substituir | BN17: =IF($B17="",0,IFERROR(SUMPRODUCT(MAX((Antropometria!$B$8:$B$407=$B17)*Antropometria!$A$8:$A$407)),0)) -> 46225
A18: =IF($B18="","","ATL-"&TEXT(ROW()-7,"000")) -> ATL-011 | B18: Pedro Henrique Coutinho | C18: PH | D18: 38155 | E18: =IFERROR(DATEDIF($D18,TODAY(),"Y"),"") -> 22 | F18: Masculino | G18: Brasileira | H18: — | I18: — | J18: 3 | K18: Adulto | L18: Central | M18: Destro | N18: Direita | O18: =IF(OR($B18="",$BN18=0),"",IFERROR(AVERAGEIFS(Antropometria!$F$8:$F$407,Antropometria!$B$8:$B$407,$B18,Antropometria!$A$8:$A$407,$BN18),"")) -> 204 | P18: =IF(OR($B18="",$BN18=0),"",IFERROR(AVERAGEIFS(Antropometria!$E$8:$E$407,Antropometria!$B$8:$B$407,$B18,Antropometria!$A$8:$A$407,$BN18),"")) -> 91.8 | Q18: =IFERROR(ROUND($P18/($O18/100)^2,1),"") -> 22.1 | R18: (00) 90000-0011 | S18: atleta11@elase.com.br | T18: — | U18: — | V18: — | W18: Responsável / familiar | X18: (00) 90000-1011 | Y18: — | Z18: Ensino Médio completo | AA18: Concluído | AB18: — | AC18: — | AD18: Não | AE18: 0 | AF18: Atleta em formação | AG18: 6 | AH18: D-E | AI18: Cedida | AJ18: Alojamento do clube | AK18: A pé | AL18: 5 | AM18: Sim | AN18: Sim | AO18: Não | AP18: Sim | AQ18: 5 | AR18: Sim | AS18: 13 | AT18: =IFERROR($E18-$AS18,"") -> 9 | AU18: 1 | AV18: Superliga B | AW18: — | AX18: Seleção estadual Sub-21 | AY18: O+ | AZ18: — | BA18: — | BB18: — | BC18: — | BD18: 0 | BE18: — | BF18: 46034 | BG18: 46399 | BH18: =IF($BG18="","",IF($BG18<TODAY(),"VENCIDO",IF($BG18<=TODAY()+30,"Vence em 30 dias","Válido"))) -> Válido | BI18: Sim | BJ18: Não | BK18: 46027 | BL18: Ativo | BM18: EXEMPLO — substituir | BN18: =IF($B18="",0,IFERROR(SUMPRODUCT(MAX((Antropometria!$B$8:$B$407=$B18)*Antropometria!$A$8:$A$407)),0)) -> 46225
A19: =IF($B19="","","ATL-"&TEXT(ROW()-7,"000")) -> ATL-012 | B19: Caio Fernandes Bastos | C19: Caio | D19: 37173 | E19: =IFERROR(DATEDIF($D19,TODAY(),"Y"),"") -> 24 | F19: Masculino | G19: Brasileira | H19: — | I19: — | J19: 1 | K19: Adulto | L19: Líbero | M19: Canhoto | N19: Direita | O19: =IF(OR($B19="",$BN19=0),"",IFERROR(AVERAGEIFS(Antropometria!$F$8:$F$407,Antropometria!$B$8:$B$407,$B19,Antropometria!$A$8:$A$407,$BN19),"")) -> 186 | P19: =IF(OR($B19="",$BN19=0),"",IFERROR(AVERAGEIFS(Antropometria!$E$8:$E$407,Antropometria!$B$8:$B$407,$B19,Antropometria!$A$8:$A$407,$BN19),"")) -> 78.2 | Q19: =IFERROR(ROUND($P19/($O19/100)^2,1),"") -> 22.6 | R19: (00) 90000-0012 | S19: atleta12@elase.com.br | T19: — | U19: — | V19: — | W19: Responsável / familiar | X19: (00) 90000-1012 | Y19: — | Z19: Superior em andamento | AA19: Cursando | AB19: Matutino | AC19: — | AD19: Sim | AE19: 12 | AF19: Auxiliar administrativo | AG19: 3 | AH19: C1 | AI19: Alugada | AJ19: Família | AK19: Transporte público | AL19: 45 | AM19: Não | AN19: Não | AO19: Sim | AP19: Sim | AQ19: 4 | AR19: Não | AS19: 12 | AT19: =IFERROR($E19-$AS19,"") -> 12 | AU19: 3 | AV19: Superliga B | AW19: — | AX19: — | AY19: O+ | AZ19: — | BA19: — | BB19: — | BC19: Entorse de dedo | BD19: 1 | BE19: — | BF19: 46034 | BG19: 46399 | BH19: =IF($BG19="","",IF($BG19<TODAY(),"VENCIDO",IF($BG19<=TODAY()+30,"Vence em 30 dias","Válido"))) -> Válido | BI19: Sim | BJ19: Não | BK19: 46027 | BL19: Ativo | BM19: EXEMPLO — substituir | BN19: =IF($B19="",0,IFERROR(SUMPRODUCT(MAX((Antropometria!$B$8:$B$407=$B19)*Antropometria!$A$8:$A$407)),0)) -> 46225
A20: =IF($B20="","","ATL-"&TEXT(ROW()-7,"000")) | E20: =IFERROR(DATEDIF($D20,TODAY(),"Y"),"") -> 126 | O20: =IF(OR($B20="",$BN20=0),"",IFERROR(AVERAGEIFS(Antropometria!$F$8:$F$407,Antropometria!$B$8:$B$407,$B20,Antropometria!$A$8:$A$407,$BN20),"")) | P20: =IF(OR($B20="",$BN20=0),"",IFERROR(AVERAGEIFS(Antropometria!$E$8:$E$407,Antropometria!$B$8:$B$407,$B20,Antropometria!$A$8:$A$407,$BN20),"")) | Q20: =IFERROR(ROUND($P20/($O20/100)^2,1),"") | AT20: =IFERROR($E20-$AS20,"") -> 126 | BH20: =IF($BG20="","",IF($BG20<TODAY(),"VENCIDO",IF($BG20<=TODAY()+30,"Vence em 30 dias","Válido"))) | BN20: =IF($B20="",0,IFERROR(SUMPRODUCT(MAX((Antropometria!$B$8:$B$407=$B20)*Antropometria!$A$8:$A$407)),0)) -> 0
A21: =IF($B21="","","ATL-"&TEXT(ROW()-7,"000")) | E21: =IFERROR(DATEDIF($D21,TODAY(),"Y"),"") -> 126 | O21: =IF(OR($B21="",$BN21=0),"",IFERROR(AVERAGEIFS(Antropometria!$F$8:$F$407,Antropometria!$B$8:$B$407,$B21,Antropometria!$A$8:$A$407,$BN21),"")) | P21: =IF(OR($B21="",$BN21=0),"",IFERROR(AVERAGEIFS(Antropometria!$E$8:$E$407,Antropometria!$B$8:$B$407,$B21,Antropometria!$A$8:$A$407,$BN21),"")) | Q21: =IFERROR(ROUND($P21/($O21/100)^2,1),"") | AT21: =IFERROR($E21-$AS21,"") -> 126 | BH21: =IF($BG21="","",IF($BG21<TODAY(),"VENCIDO",IF($BG21<=TODAY()+30,"Vence em 30 dias","Válido"))) | BN21: =IF($B21="",0,IFERROR(SUMPRODUCT(MAX((Antropometria!$B$8:$B$407=$B21)*Antropometria!$A$8:$A$407)),0)) -> 0
A22: =IF($B22="","","ATL-"&TEXT(ROW()-7,"000")) | E22: =IFERROR(DATEDIF($D22,TODAY(),"Y"),"") -> 126 | O22: =IF(OR($B22="",$BN22=0),"",IFERROR(AVERAGEIFS(Antropometria!$F$8:$F$407,Antropometria!$B$8:$B$407,$B22,Antropometria!$A$8:$A$407,$BN22),"")) | P22: =IF(OR($B22="",$BN22=0),"",IFERROR(AVERAGEIFS(Antropometria!$E$8:$E$407,Antropometria!$B$8:$B$407,$B22,Antropometria!$A$8:$A$407,$BN22),"")) | Q22: =IFERROR(ROUND($P22/($O22/100)^2,1),"") | AT22: =IFERROR($E22-$AS22,"") -> 126 | BH22: =IF($BG22="","",IF($BG22<TODAY(),"VENCIDO",IF($BG22<=TODAY()+30,"Vence em 30 dias","Válido"))) | BN22: =IF($B22="",0,IFERROR(SUMPRODUCT(MAX((Antropometria!$B$8:$B$407=$B22)*Antropometria!$A$8:$A$407)),0)) -> 0
A23: =IF($B23="","","ATL-"&TEXT(ROW()-7,"000")) | E23: =IFERROR(DATEDIF($D23,TODAY(),"Y"),"") -> 126 | O23: =IF(OR($B23="",$BN23=0),"",IFERROR(AVERAGEIFS(Antropometria!$F$8:$F$407,Antropometria!$B$8:$B$407,$B23,Antropometria!$A$8:$A$407,$BN23),"")) | P23: =IF(OR($B23="",$BN23=0),"",IFERROR(AVERAGEIFS(Antropometria!$E$8:$E$407,Antropometria!$B$8:$B$407,$B23,Antropometria!$A$8:$A$407,$BN23),"")) | Q23: =IFERROR(ROUND($P23/($O23/100)^2,1),"") | AT23: =IFERROR($E23-$AS23,"") -> 126 | BH23: =IF($BG23="","",IF($BG23<TODAY(),"VENCIDO",IF($BG23<=TODAY()+30,"Vence em 30 dias","Válido"))) | BN23: =IF($B23="",0,IFERROR(SUMPRODUCT(MAX((Antropometria!$B$8:$B$407=$B23)*Antropometria!$A$8:$A$407)),0)) -> 0
A24: =IF($B24="","","ATL-"&TEXT(ROW()-7,"000")) | E24: =IFERROR(DATEDIF($D24,TODAY(),"Y"),"") -> 126 | O24: =IF(OR($B24="",$BN24=0),"",IFERROR(AVERAGEIFS(Antropometria!$F$8:$F$407,Antropometria!$B$8:$B$407,$B24,Antropometria!$A$8:$A$407,$BN24),"")) | P24: =IF(OR($B24="",$BN24=0),"",IFERROR(AVERAGEIFS(Antropometria!$E$8:$E$407,Antropometria!$B$8:$B$407,$B24,Antropometria!$A$8:$A$407,$BN24),"")) | Q24: =IFERROR(ROUND($P24/($O24/100)^2,1),"") | AT24: =IFERROR($E24-$AS24,"") -> 126 | BH24: =IF($BG24="","",IF($BG24<TODAY(),"VENCIDO",IF($BG24<=TODAY()+30,"Vence em 30 dias","Válido"))) | BN24: =IF($B24="",0,IFERROR(SUMPRODUCT(MAX((Antropometria!$B$8:$B$407=$B24)*Antropometria!$A$8:$A$407)),0)) -> 0
A25: =IF($B25="","","ATL-"&TEXT(ROW()-7,"000")) | E25: =IFERROR(DATEDIF($D25,TODAY(),"Y"),"") -> 126 | O25: =IF(OR($B25="",$BN25=0),"",IFERROR(AVERAGEIFS(Antropometria!$F$8:$F$407,Antropometria!$B$8:$B$407,$B25,Antropometria!$A$8:$A$407,$BN25),"")) | P25: =IF(OR($B25="",$BN25=0),"",IFERROR(AVERAGEIFS(Antropometria!$E$8:$E$407,Antropometria!$B$8:$B$407,$B25,Antropometria!$A$8:$A$407,$BN25),"")) | Q25: =IFERROR(ROUND($P25/($O25/100)^2,1),"") | AT25: =IFERROR($E25-$AS25,"") -> 126 | BH25: =IF($BG25="","",IF($BG25<TODAY(),"VENCIDO",IF($BG25<=TODAY()+30,"Vence em 30 dias","Válido"))) | BN25: =IF($B25="",0,IFERROR(SUMPRODUCT(MAX((Antropometria!$B$8:$B$407=$B25)*Antropometria!$A$8:$A$407)),0)) -> 0
A26: =IF($B26="","","ATL-"&TEXT(ROW()-7,"000")) | E26: =IFERROR(DATEDIF($D26,TODAY(),"Y"),"") -> 126 | O26: =IF(OR($B26="",$BN26=0),"",IFERROR(AVERAGEIFS(Antropometria!$F$8:$F$407,Antropometria!$B$8:$B$407,$B26,Antropometria!$A$8:$A$407,$BN26),"")) | P26: =IF(OR($B26="",$BN26=0),"",IFERROR(AVERAGEIFS(Antropometria!$E$8:$E$407,Antropometria!$B$8:$B$407,$B26,Antropometria!$A$8:$A$407,$BN26),"")) | Q26: =IFERROR(ROUND($P26/($O26/100)^2,1),"") | AT26: =IFERROR($E26-$AS26,"") -> 126 | BH26: =IF($BG26="","",IF($BG26<TODAY(),"VENCIDO",IF($BG26<=TODAY()+30,"Vence em 30 dias","Válido"))) | BN26: =IF($B26="",0,IFERROR(SUMPRODUCT(MAX((Antropometria!$B$8:$B$407=$B26)*Antropometria!$A$8:$A$407)),0)) -> 0
A27: =IF($B27="","","ATL-"&TEXT(ROW()-7,"000")) | E27: =IFERROR(DATEDIF($D27,TODAY(),"Y"),"") -> 126 | O27: =IF(OR($B27="",$BN27=0),"",IFERROR(AVERAGEIFS(Antropometria!$F$8:$F$407,Antropometria!$B$8:$B$407,$B27,Antropometria!$A$8:$A$407,$BN27),"")) | P27: =IF(OR($B27="",$BN27=0),"",IFERROR(AVERAGEIFS(Antropometria!$E$8:$E$407,Antropometria!$B$8:$B$407,$B27,Antropometria!$A$8:$A$407,$BN27),"")) | Q27: =IFERROR(ROUND($P27/($O27/100)^2,1),"") | AT27: =IFERROR($E27-$AS27,"") -> 126 | BH27: =IF($BG27="","",IF($BG27<TODAY(),"VENCIDO",IF($BG27<=TODAY()+30,"Vence em 30 dias","Válido"))) | BN27: =IF($B27="",0,IFERROR(SUMPRODUCT(MAX((Antropometria!$B$8:$B$407=$B27)*Antropometria!$A$8:$A$407)),0)) -> 0
A28: =IF($B28="","","ATL-"&TEXT(ROW()-7,"000")) | E28: =IFERROR(DATEDIF($D28,TODAY(),"Y"),"") -> 126 | O28: =IF(OR($B28="",$BN28=0),"",IFERROR(AVERAGEIFS(Antropometria!$F$8:$F$407,Antropometria!$B$8:$B$407,$B28,Antropometria!$A$8:$A$407,$BN28),"")) | P28: =IF(OR($B28="",$BN28=0),"",IFERROR(AVERAGEIFS(Antropometria!$E$8:$E$407,Antropometria!$B$8:$B$407,$B28,Antropometria!$A$8:$A$407,$BN28),"")) | Q28: =IFERROR(ROUND($P28/($O28/100)^2,1),"") | AT28: =IFERROR($E28-$AS28,"") -> 126 | BH28: =IF($BG28="","",IF($BG28<TODAY(),"VENCIDO",IF($BG28<=TODAY()+30,"Vence em 30 dias","Válido"))) | BN28: =IF($B28="",0,IFERROR(SUMPRODUCT(MAX((Antropometria!$B$8:$B$407=$B28)*Antropometria!$A$8:$A$407)),0)) -> 0
A29: =IF($B29="","","ATL-"&TEXT(ROW()-7,"000")) | E29: =IFERROR(DATEDIF($D29,TODAY(),"Y"),"") -> 126 | O29: =IF(OR($B29="",$BN29=0),"",IFERROR(AVERAGEIFS(Antropometria!$F$8:$F$407,Antropometria!$B$8:$B$407,$B29,Antropometria!$A$8:$A$407,$BN29),"")) | P29: =IF(OR($B29="",$BN29=0),"",IFERROR(AVERAGEIFS(Antropometria!$E$8:$E$407,Antropometria!$B$8:$B$407,$B29,Antropometria!$A$8:$A$407,$BN29),"")) | Q29: =IFERROR(ROUND($P29/($O29/100)^2,1),"") | AT29: =IFERROR($E29-$AS29,"") -> 126 | BH29: =IF($BG29="","",IF($BG29<TODAY(),"VENCIDO",IF($BG29<=TODAY()+30,"Vence em 30 dias","Válido"))) | BN29: =IF($B29="",0,IFERROR(SUMPRODUCT(MAX((Antropometria!$B$8:$B$407=$B29)*Antropometria!$A$8:$A$407)),0)) -> 0
A30: =IF($B30="","","ATL-"&TEXT(ROW()-7,"000")) | E30: =IFERROR(DATEDIF($D30,TODAY(),"Y"),"") -> 126 | O30: =IF(OR($B30="",$BN30=0),"",IFERROR(AVERAGEIFS(Antropometria!$F$8:$F$407,Antropometria!$B$8:$B$407,$B30,Antropometria!$A$8:$A$407,$BN30),"")) | P30: =IF(OR($B30="",$BN30=0),"",IFERROR(AVERAGEIFS(Antropometria!$E$8:$E$407,Antropometria!$B$8:$B$407,$B30,Antropometria!$A$8:$A$407,$BN30),"")) | Q30: =IFERROR(ROUND($P30/($O30/100)^2,1),"") | AT30: =IFERROR($E30-$AS30,"") -> 126 | BH30: =IF($BG30="","",IF($BG30<TODAY(),"VENCIDO",IF($BG30<=TODAY()+30,"Vence em 30 dias","Válido"))) | BN30: =IF($B30="",0,IFERROR(SUMPRODUCT(MAX((Antropometria!$B$8:$B$407=$B30)*Antropometria!$A$8:$A$407)),0)) -> 0
A31: =IF($B31="","","ATL-"&TEXT(ROW()-7,"000")) | E31: =IFERROR(DATEDIF($D31,TODAY(),"Y"),"") -> 126 | O31: =IF(OR($B31="",$BN31=0),"",IFERROR(AVERAGEIFS(Antropometria!$F$8:$F$407,Antropometria!$B$8:$B$407,$B31,Antropometria!$A$8:$A$407,$BN31),"")) | P31: =IF(OR($B31="",$BN31=0),"",IFERROR(AVERAGEIFS(Antropometria!$E$8:$E$407,Antropometria!$B$8:$B$407,$B31,Antropometria!$A$8:$A$407,$BN31),"")) | Q31: =IFERROR(ROUND($P31/($O31/100)^2,1),"") | AT31: =IFERROR($E31-$AS31,"") -> 126 | BH31: =IF($BG31="","",IF($BG31<TODAY(),"VENCIDO",IF($BG31<=TODAY()+30,"Vence em 30 dias","Válido"))) | BN31: =IF($B31="",0,IFERROR(SUMPRODUCT(MAX((Antropometria!$B$8:$B$407=$B31)*Antropometria!$A$8:$A$407)),0)) -> 0
... A47: =IF($B47="","","ATL-"&TEXT(ROW()-7,"000")) | E47: =IFERROR(DATEDIF($D47,TODAY(),"Y"),"") -> 126 | O47: =IF(OR($B47="",$BN47=0),"",IFERROR(AVERAGEIFS(Antropometria!$F$8:$F$407,Antropometria!$B$8:$B$407,$B47,Antropometria!$A$8:$A$407,$BN47),"")) | P47: =IF(OR($B47="",$BN47=0),"",IFERROR(AVERAGEIFS(Antropometria!$E$8:$E$407,Antropometria!$B$8:$B$407,$B47,Antropometria!$A$8:$A$407,$BN47),"")) | Q47: =IFERROR(ROUND($P47/($O47/100)^2,1),"") | AT47: =IFERROR($E47-$AS47,"") -> 126 | BH47: =IF($BG47="","",IF($BG47<TODAY(),"VENCIDO",IF($BG47<=TODAY()+30,"Vence em 30 dias","Válido"))) | BN47: =IF($B47="",0,IFERROR(SUMPRODUCT(MAX((Antropometria!$B$8:$B$407=$B47)*Antropometria!$A$8:$A$407)),0)) -> 0

Sheet Antropometria
A1: ANTROPOMETRIA E COMPOSIÇÃO CORPORAL
A2: Avaliações longitudinais. Preencha as medidas em amarelo; densidade, % de gordura, massa magra, índices e somatotipo são calculados. Sexo e data de nascimento são lidos do Cadastro.
A4: Protocolo: perfil restrito ISAK. Dobras em mm, perímetros e diâmetros em cm. • % de gordura pela equação de 7 dobras de Jackson & Pollock (1978 masculino / 1980 feminino) com conversão de Siri (1961) — a planilha escolhe a equação pelo sexo cadastrado. • Somatotipo pelo método Heath-Carter. • Σ 7 Dobras JP = peitoral + axilar média + tríceps + subescapular + abdominal + suprailíaca + coxa medial.
A6: IDENTIFICAÇÃO E MEDIDAS BÁSICAS | I6: DOBRAS CUTÂNEAS (mm) | S6: PERÍMETROS (cm) | AC6: DIÂMETROS ÓSSEOS (cm) | AG6: CALCULADOS
A7: Data | B7: Atleta | C7: Momento | D7: Avaliador | E7: Massa (kg) | F7: Estatura (cm) | G7: Estatura Sentado (cm) | H7: Envergadura (cm) | I7: Tríceps | J7: Subescapular | K7: Bíceps | L7: Peitoral | M7: Axilar Média | N7: Suprailíaca | O7: Supraespinhal | P7: Abdominal | Q7: Coxa Medial | R7: Perna Medial | S7: Braço Relaxado | T7: Braço Contraído | U7: Antebraço | V7: Tórax | W7: Cintura | X7: Abdômen | Y7: Quadril | Z7: Coxa (1/3) | AA7: Perna | AB7: Punho | AC7: Biacromial | AD7: Biileocristal | AE7: Úmero | AF7: Fêmur | AG7: Idade na Avaliação | AH7: Σ 4 Dobras (mm) | AI7: Σ 7 Dobras JP (mm) | AJ7: Σ 8 Dobras (mm) | AK7: Densidade Corporal | AL7: % de Gordura | AM7: Massa Gorda (kg) | AN7: Massa Magra (kg) | AO7: IMC | AP7: Índice Córmico | AQ7: Cintura / Estatura | AR7: AMB (cm²) | AS7: Endomorfia | AT7: Mesomorfia | AU7: Ectomorfia | AV7: Somatotipo Dominante
A8: 46034 | B8: Rafael Monteiro Alves | C8: Pré-temporada | D8: Comissão técnica | E8: 88 | F8: 196 | G8: 102.3 | H8: 201.9 | I8: 8.1 | J8: 13 | K8: 5.4 | L8: 6.9 | M8: 7 | N8: 10 | O8: 8 | P8: 14.1 | Q8: 9.7 | R8: 6.8 | S8: 34.8 | T8: 36.3 | U8: 27.1 | V8: 98.5 | W8: 85.6 | X8: 82.2 | Y8: 101.6 | Z8: 60.2 | AA8: 38.1 | AB8: 18.5 | AC8: 44.1 | AD8: 27.7 | AE8: 7.3 | AF8: 10.2 | AG8: =IFERROR(DATEDIF(INDEX(Cadastro!$D$8:$D$47,MATCH($B8,Cadastro!$B$8:$B$47,0)),$A8,"Y"),"") -> 27 | AH8: =IF(COUNT($I8,$K8,$J8,$N8)<4,"",$I8+$K8+$J8+$N8) -> 36.5 | AI8: =IF(COUNT($L8,$M8,$I8,$J8,$P8,$N8,$Q8)<7,"",$L8+$M8+$I8+$J8+$P8+$N8+$Q8) -> 68.8 | AJ8: =IF(COUNT($I8,$J8,$K8,$O8,$P8,$Q8,$R8,$N8)<8,"",$I8+$J8+$K8+$O8+$P8+$Q8+$R8+$N8) -> 75.1 | AK8: =IF(OR($AI8="",$AG8=""),"",IF(IFERROR(INDEX(Cadastro!$F$8:$F$47,MATCH($B8,Cadastro!$B$8:$B$47,0)),"")="Feminino",1.097-0.00046971*$AI8+0.00000056*$AI8^2-0.00012828*$AG8,1.112-0.00043499*$AI8+0.00000055*$AI8^2-0.00028826*$AG8)) -> 1.0768931 | AL8: =IF(OR($AK8="",$AK8=0),"",495/$AK8-450) -> 9.6556691 | AM8: =IF(OR($AL8="",$E8=""),"",$E8*$AL8/100) -> 8.4969888 | AN8: =IF(OR($AM8="",$E8=""),"",$E8-$AM8) -> 79.503011 | AO8: =IFERROR($E8/($F8/100)^2,"") -> 22.907122 | AP8: =IFERROR($G8/$F8*100,"") -> 52.193878 | AQ8: =IFERROR($W8/$F8,"") -> 0.43673469 | AR8: =IF(OR($S8="",$I8=""),"",($S8-PI()*$I8/10)^2/(4*PI())-IF(IFERROR(INDEX(Cadastro!$F$8:$F$47,MATCH($B8,Cadastro!$B$8:$B$47,0)),"")="Feminino",6.5,10)) -> 72.792801 | AS8: =IF(OR($I8="",$J8="",$O8="",$F8=""),"",-0.7182+0.1451*(($I8+$J8+$O8)*(170.18/$F8))-0.00068*(($I8+$J8+$O8)*(170.18/$F8))^2+0.0000014*(($I8+$J8+$O8)*(170.18/$F8))^3) -> 2.5364442 | AT8: =IF(OR($AE8="",$AF8="",$T8="",$AA8="",$F8=""),"",0.858*$AE8+0.601*$AF8+0.188*($T8-$I8/10)+0.161*($AA8-$R8/10)-0.131*$F8+4.5) -> 3.91434 | AU8: =IF(OR($E8="",$F8=""),"",IF($F8/$E8^(1/3)>=40.75,0.732*($F8/$E8^(1/3))-28.58,IF($F8/$E8^(1/3)>=38.25,0.463*($F8/$E8^(1/3))-17.63,0.1))) -> 3.6756844 | AV8: =IF(OR($AS8="",$AT8="",$AU8=""),"",IF(AND($AT8>=$AS8,$AT8>=$AU8),"Mesomorfo dominante",IF(AND($AU8>=$AS8,$AU8>=$AT8),"Ectomorfo dominante","Endomorfo dominante"))) -> Mesomorfo dominante
A9: 46034 | B9: Diego Salgado Ferraz | C9: Pré-temporada | D9: Comissão técnica | E9: 95 | F9: 202 | G9: 105.4 | H9: 207 | I9: 9 | J9: 12.4 | K9: 3.1 | L9: 6.3 | M9: 7.9 | N9: 9.1 | O9: 7 | P9: 11.8 | Q9: 9.1 | R9: 6.8 | S9: 33.8 | T9: 33.7 | U9: 29.3 | V9: 99.9 | W9: 84.2 | X9: 87.8 | Y9: 98.3 | Z9: 56.3 | AA9: 39.3 | AB9: 18.5 | AC9: 42.4 | AD9: 29.8 | AE9: 7.5 | AF9: 9.6 | AG9: =IFERROR(DATEDIF(INDEX(Cadastro!$D$8:$D$47,MATCH($B9,Cadastro!$B$8:$B$47,0)),$A9,"Y"),"") -> 29 | AH9: =IF(COUNT($I9,$K9,$J9,$N9)<4,"",$I9+$K9+$J9+$N9) -> 33.6 | AI9: =IF(COUNT($L9,$M9,$I9,$J9,$P9,$N9,$Q9)<7,"",$L9+$M9+$I9+$J9+$P9+$N9+$Q9) -> 65.6 | AJ9: =IF(COUNT($I9,$J9,$K9,$O9,$P9,$Q9,$R9,$N9)<8,"",$I9+$J9+$K9+$O9+$P9+$Q9+$R9+$N9) -> 68.3 | AK9: =IF(OR($AI9="",$AG9=""),"",IF(IFERROR(INDEX(Cadastro!$F$8:$F$47,MATCH($B9,Cadastro!$B$8:$B$47,0)),"")="Feminino",1.097-0.00046971*$AI9+0.00000056*$AI9^2-0.00012828*$AG9,1.112-0.00043499*$AI9+0.00000055*$AI9^2-0.00028826*$AG9)) -> 1.077472 | AL9: =IF(OR($AK9="",$AK9=0),"",495/$AK9-450) -> 9.4087053 | AM9: =IF(OR($AL9="",$E9=""),"",$E9*$AL9/100) -> 8.9382701 | AN9: =IF(OR($AM9="",$E9=""),"",$E9-$AM9) -> 86.06173 | AO9: =IFERROR($E9/($F9/100)^2,"") -> 23.282031 | AP9: =IFERROR($G9/$F9*100,"") -> 52.178218 | AQ9: =IFERROR($W9/$F9,"") -> 0.41683168 | AR9: =IF(OR($S9="",$I9=""),"",($S9-PI()*$I9/10)^2/(4*PI())-IF(IFERROR(INDEX(Cadastro!$F$8:$F$47,MATCH($B9,Cadastro!$B$8:$B$47,0)),"")="Feminino",6.5,10)) -> 66.338659 | AS9: =IF(OR($I9="",$J9="",$O9="",$F9=""),"",-0.7182+0.1451*(($I9+$J9+$O9)*(170.18/$F9))-0.00068*(($I9+$J9+$O9)*(170.18/$F9))^2+0.0000014*(($I9+$J9+$O9)*(170.18/$F9))^3) -> 2.3834035 | AT9: =IF(OR($AE9="",$AF9="",$T9="",$AA9="",$F9=""),"",0.858*$AE9+0.601*$AF9+0.188*($T9-$I9/10)+0.161*($AA9-$R9/10)-0.131*$F9+4.5) -> 2.62682 | AU9: =IF(OR($E9="",$F9=""),"",IF($F9/$E9^(1/3)>=40.75,0.732*($F9/$E9^(1/3))-28.58,IF($F9/$E9^(1/3)>=38.25,0.463*($F9/$E9^(1/3))-17.63,0.1))) -> 3.8256882 | AV9: =IF(OR($AS9="",$AT9="",$AU9=""),"",IF(AND($AT9>=$AS9,$AT9>=$AU9),"Mesomorfo dominante",IF(AND($AU9>=$AS9,$AU9>=$AT9),"Ectomorfo dominante","Endomorfo dominante"))) -> Ectomorfo dominante
A10: 46034 | B10: Lucas Prado Bittencourt | C10: Pré-temporada | D10: Comissão técnica | E10: 89 | F10: 198 | G10: 103.4 | H10: 203 | I10: 9.3 | J10: 9.5 | K10: 5.5 | L10: 6.4 | M10: 7.3 | N10: 13.8 | O10: 8.3 | P10: 14.9 | Q10: 11.1 | R10: 8 | S10: 31.3 | T10: 35.3 | U10: 28.7 | V10: 99.1 | W10: 84.8 | X10: 81.3 | Y10: 96.5 | Z10: 59.4 | AA10: 40.7 | AB10: 18.6 | AC10: 44.5 | AD10: 28.6 | AE10: 7.3 | AF10: 9.6 | AG10: =IFERROR(DATEDIF(INDEX(Cadastro!$D$8:$D$47,MATCH($B10,Cadastro!$B$8:$B$47,0)),$A10,"Y"),"") -> 25 | AH10: =IF(COUNT($I10,$K10,$J10,$N10)<4,"",$I10+$K10+$J10+$N10) -> 38.1 | AI10: =IF(COUNT($L10,$M10,$I10,$J10,$P10,$N10,$Q10)<7,"",$L10+$M10+$I10+$J10+$P10+$N10+$Q10) -> 72.3 | AJ10: =IF(COUNT($I10,$J10,$K10,$O10,$P10,$Q10,$R10,$N10)<8,"",$I10+$J10+$K10+$O10+$P10+$Q10+$R10+$N10) -> 80.4 | AK10: =IF(OR($AI10="",$AG10=""),"",IF(IFERROR(INDEX(Cadastro!$F$8:$F$47,MATCH($B10,Cadastro!$B$8:$B$47,0)),"")="Feminino",1.097-0.00046971*$AI10+0.00000056*$AI10^2-0.00012828*$AG10,1.112-0.00043499*$AI10+0.00000055*$AI10^2-0.00028826*$AG10)) -> 1.0762187 | AL10: =IF(OR($AK10="",$AK10=0),"",495/$AK10-450) -> 9.943676 | AM10: =IF(OR($AL10="",$E10=""),"",$E10*$AL10/100) -> 8.8498716 | AN10: =IF(OR($AM10="",$E10=""),"",$E10-$AM10) -> 80.150128 | AO10: =IFERROR($E10/($F10/100)^2,"") -> 22.701765 | AP10: =IFERROR($G10/$F10*100,"") -> 52.222222 | AQ10: =IFERROR($W10/$F10,"") -> 0.42828283 | AR10: =IF(OR($S10="",$I10=""),"",($S10-PI()*$I10/10)^2/(4*PI())-IF(IFERROR(INDEX(Cadastro!$F$8:$F$47,MATCH($B10,Cadastro!$B$8:$B$47,0)),"")="Feminino",6.5,10)) -> 54.086044 | AS10: =IF(OR($I10="",$J10="",$O10="",$F10=""),"",-0.7182+0.1451*(($I10+$J10+$O10)*(170.18/$F10))-0.00068*(($I10+$J10+$O10)*(170.18/$F10))^2+0.0000014*(($I10+$J10+$O10)*(170.18/$F10))^3) -> 2.3102845 | AT10: =IF(OR($AE10="",$AF10="",$T10="",$AA10="",$F10=""),"",0.858*$AE10+0.601*$AF10+0.188*($T10-$I10/10)+0.161*($AA10-$R10/10)-0.131*$F10+4.5) -> 3.48046 | AU10: =IF(OR($E10="",$F10=""),"",IF($F10/$E10^(1/3)>=40.75,0.732*($F10/$E10^(1/3))-28.58,IF($F10/$E10^(1/3)>=38.25,0.463*($F10/$E10^(1/3))-17.63,0.1))) -> 3.8823236 | AV10: =IF(OR($AS10="",$AT10="",$AU10=""),"",IF(AND($AT10>=$AS10,$AT10>=$AU10),"Mesomorfo dominante",IF(AND($AU10>=$AS10,$AU10>=$AT10),"Ectomorfo dominante","Endomorfo dominante"))) -> Ectomorfo dominante
A11: 46034 | B11: Bruno Rezende Camargo | C11: Pré-temporada | D11: Comissão técnica | E11: 87 | F11: 197 | G11: 102.8 | H11: 202.6 | I11: 9.4 | J11: 9.7 | K11: 3 | L11: 6.4 | M11: 7.4 | N11: 13.7 | O11: 9.2 | P11: 16.6 | Q11: 13.2 | R11: 8.8 | S11: 31.6 | T11: 36.4 | U11: 29.2 | V11: 99.2 | W11: 81.4 | X11: 83.8 | Y11: 100.6 | Z11: 55.4 | AA11: 37.2 | AB11: 17.9 | AC11: 42.4 | AD11: 28.8 | AE11: 7.5 | AF11: 9.9 | AG11: =IFERROR(DATEDIF(INDEX(Cadastro!$D$8:$D$47,MATCH($B11,Cadastro!$B$8:$B$47,0)),$A11,"Y"),"") -> 26 | AH11: =IF(COUNT($I11,$K11,$J11,$N11)<4,"",$I11+$K11+$J11+$N11) -> 35.8 | AI11: =IF(COUNT($L11,$M11,$I11,$J11,$P11,$N11,$Q11)<7,"",$L11+$M11+$I11+$J11+$P11+$N11+$Q11) -> 76.4 | AJ11: =IF(COUNT($I11,$J11,$K11,$O11,$P11,$Q11,$R11,$N11)<8,"",$I11+$J11+$K11+$O11+$P11+$Q11+$R11+$N11) -> 83.6 | AK11: =IF(OR($AI11="",$AG11=""),"",IF(IFERROR(INDEX(Cadastro!$F$8:$F$47,MATCH($B11,Cadastro!$B$8:$B$47,0)),"")="Feminino",1.097-0.00046971*$AI11+0.00000056*$AI11^2-0.00012828*$AG11,1.112-0.00043499*$AI11+0.00000055*$AI11^2-0.00028826*$AG11)) -> 1.0744823 | AL11: =IF(OR($AK11="",$AK11=0),"",495/$AK11-450) -> 10.686961 | AM11: =IF(OR($AL11="",$E11=""),"",$E11*$AL11/100) -> 9.2976559 | AN11: =IF(OR($AM11="",$E11=""),"",$E11-$AM11) -> 77.702344 | AO11: =IFERROR($E11/($F11/100)^2,"") -> 22.41748 | AP11: =IFERROR($G11/$F11*100,"") -> 52.182741 | AQ11: =IFERROR($W11/$F11,"") -> 0.41319797 | AR11: =IF(OR($S11="",$I11=""),"",($S11-PI()*$I11/10)^2/(4*PI())-IF(IFERROR(INDEX(Cadastro!$F$8:$F$47,MATCH($B11,Cadastro!$B$8:$B$47,0)),"")="Feminino",6.5,10)) -> 55.304858 | AS11: =IF(OR($I11="",$J11="",$O11="",$F11=""),"",-0.7182+0.1451*(($I11+$J11+$O11)*(170.18/$F11))-0.00068*(($I11+$J11+$O11)*(170.18/$F11))^2+0.0000014*(($I11+$J11+$O11)*(170.18/$F11))^3) -> 2.4431293 | AT11: =IF(OR($AE11="",$AF11="",$T11="",$AA11="",$F11=""),"",0.858*$AE11+0.601*$AF11+0.188*($T11-$I11/10)+0.161*($AA11-$R11/10)-0.131*$F11+4.5) -> 3.5919 | AU11: =IF(OR($E11="",$F11=""),"",IF($F11/$E11^(1/3)>=40.75,0.732*($F11/$E11^(1/3))-28.58,IF($F11/$E11^(1/3)>=38.25,0.463*($F11/$E11^(1/3))-17.63,0.1))) -> 3.9639969 | AV11: =IF(OR($AS11="",$AT11="",$AU11=""),"",IF(AND($AT11>=$AS11,$AT11>=$AU11),"Mesomorfo dominante",IF(AND($AU11>=$AS11,$AU11>=$AT11),"Ectomorfo dominante","Endomorfo dominante"))) -> Ectomorfo dominante
A12: 46034 | B12: Thiago Nogueira Vasques | C12: Pré-temporada | D12: Comissão técnica | E12: 99 | F12: 205 | G12: 107 | H12: 209.6 | I12: 8.5 | J12: 11.9 | K12: 5.5 | L12: 7.7 | M12: 6.5 | N12: 12 | O12: 6.5 | P12: 16.3 | Q12: 12 | R12: 9.7 | S12: 31.1 | T12: 37.4 | U12: 29.3 | V12: 96.7 | W12: 80.9 | X12: 85 | Y12: 98.9 | Z12: 61.2 | AA12: 38.9 | AB12: 18 | AC12: 44.6 | AD12: 27.7 | AE12: 7.3 | AF12: 9.5 | AG12: =IFERROR(DATEDIF(INDEX(Cadastro!$D$8:$D$47,MATCH($B12,Cadastro!$B$8:$B$47,0)),$A12,"Y"),"") -> 30 | AH12: =IF(COUNT($I12,$K12,$J12,$N12)<4,"",$I12+$K12+$J12+$N12) -> 37.9 | AI12: =IF(COUNT($L12,$M12,$I12,$J12,$P12,$N12,$Q12)<7,"",$L12+$M12+$I12+$J12+$P12+$N12+$Q12) -> 74.9 | AJ12: =IF(COUNT($I12,$J12,$K12,$O12,$P12,$Q12,$R12,$N12)<8,"",$I12+$J12+$K12+$O12+$P12+$Q12+$R12+$N12) -> 82.4 | AK12: =IF(OR($AI12="",$AG12=""),"",IF(IFERROR(INDEX(Cadastro!$F$8:$F$47,MATCH($B12,Cadastro!$B$8:$B$47,0)),"")="Feminino",1.097-0.00046971*$AI12+0.00000056*$AI12^2-0.00012828*$AG12,1.112-0.00043499*$AI12+0.00000055*$AI12^2-0.00028826*$AG12)) -> 1.073857 | AL12: =IF(OR($AK12="",$AK12=0),"",495/$AK12-450) -> 10.955249 | AM12: =IF(OR($AL12="",$E12=""),"",$E12*$AL12/100) -> 10.845697 | AN12: =IF(OR($AM12="",$E12=""),"",$E12-$AM12) -> 88.154303 | AO12: =IFERROR($E12/($F12/100)^2,"") -> 23.557406 | AP12: =IFERROR($G12/$F12*100,"") -> 52.195122 | AQ12: =IFERROR($W12/$F12,"") -> 0.39463415 | AR12: =IF(OR($S12="",$I12=""),"",($S12-PI()*$I12/10)^2/(4*PI())-IF(IFERROR(INDEX(Cadastro!$F$8:$F$47,MATCH($B12,Cadastro!$B$8:$B$47,0)),"")="Feminino",6.5,10)) -> 54.318076 | AS12: =IF(OR($I12="",$J12="",$O12="",$F12=""),"",-0.7182+0.1451*(($I12+$J12+$O12)*(170.18/$F12))-0.00068*(($I12+$J12+$O12)*(170.18/$F12))^2+0.0000014*(($I12+$J12+$O12)*(170.18/$F12))^3) -> 2.1985129 | AT12: =IF(OR($AE12="",$AF12="",$T12="",$AA12="",$F12=""),"",0.858*$AE12+0.601*$AF12+0.188*($T12-$I12/10)+0.161*($AA12-$R12/10)-0.131*$F12+4.5) -> 2.59603 | AU12: =IF(OR($E12="",$F12=""),"",IF($F12/$E12^(1/3)>=40.75,0.732*($F12/$E12^(1/3))-28.58,IF($F12/$E12^(1/3)>=38.25,0.463*($F12/$E12^(1/3))-17.63,0.1))) -> 3.8579358 | AV12: =IF(OR($AS12="",$AT12="",$AU12=""),"",IF(AND($AT12>=$AS12,$AT12>=$AU12),"Mesomorfo dominante",IF(AND($AU12>=$AS12,$AU12>=$AT12),"Ectomorfo dominante","Endomorfo dominante"))) -> Ectomorfo dominante
A13: 46034 | B13: Matheus Caldeira Lins | C13: Pré-temporada | D13: Comissão técnica | E13: 95 | F13: 203 | G13: 106 | H13: 206.8 | I13: 10 | J13: 9.1 | K13: 3.5 | L13: 6.3 | M13: 8.6 | N13: 12.4 | O13: 8 | P13: 10 | Q13: 10.7 | R13: 8.2 | S13: 32.5 | T13: 35.1 | U13: 28.6 | V13: 104.3 | W13: 83.2 | X13: 85.3 | Y13: 100.6 | Z13: 57.4 | AA13: 37.6 | AB13: 18.8 | AC13: 44.2 | AD13: 27.6 | AE13: 7.5 | AF13: 9.9 | AG13: =IFERROR(DATEDIF(INDEX(Cadastro!$D$8:$D$47,MATCH($B13,Cadastro!$B$8:$B$47,0)),$A13,"Y"),"") -> 24 | AH13: =IF(COUNT($I13,$K13,$J13,$N13)<4,"",$I13+$K13+$J13+$N13) -> 35 | AI13: =IF(COUNT($L13,$M13,$I13,$J13,$P13,$N13,$Q13)<7,"",$L13+$M13+$I13+$J13+$P13+$N13+$Q13) -> 67.1 | AJ13: =IF(COUNT($I13,$J13,$K13,$O13,$P13,$Q13,$R13,$N13)<8,"",$I13+$J13+$K13+$O13+$P13+$Q13+$R13+$N13) -> 71.9 | AK13: =IF(OR($AI13="",$AG13=""),"",IF(IFERROR(INDEX(Cadastro!$F$8:$F$47,MATCH($B13,Cadastro!$B$8:$B$47,0)),"")="Feminino",1.097-0.00046971*$AI13+0.00000056*$AI13^2-0.00012828*$AG13,1.112-0.00043499*$AI13+0.00000055*$AI13^2-0.00028826*$AG13)) -> 1.0783703 | AL13: =IF(OR($AK13="",$AK13=0),"",495/$AK13-450) -> 9.0260136 | AM13: =IF(OR($AL13="",$E13=""),"",$E13*$AL13/100) -> 8.5747129 | AN13: =IF(OR($AM13="",$E13=""),"",$E13-$AM13) -> 86.425287 | AO13: =IFERROR($E13/($F13/100)^2,"") -> 23.053217 | AP13: =IFERROR($G13/$F13*100,"") -> 52.216749 | AQ13: =IFERROR($W13/$F13,"") -> 0.40985222 | AR13: =IF(OR($S13="",$I13=""),"",($S13-PI()*$I13/10)^2/(4*PI())-IF(IFERROR(INDEX(Cadastro!$F$8:$F$47,MATCH($B13,Cadastro!$B$8:$B$47,0)),"")="Feminino",6.5,10)) -> 58.589102 | AS13: =IF(OR($I13="",$J13="",$O13="",$F13=""),"",-0.7182+0.1451*(($I13+$J13+$O13)*(170.18/$F13))-0.00068*(($I13+$J13+$O13)*(170.18/$F13))^2+0.0000014*(($I13+$J13+$O13)*(170.18/$F13))^3) -> 2.2437147 | AT13: =IF(OR($AE13="",$AF13="",$T13="",$AA13="",$F13=""),"",0.858*$AE13+0.601*$AF13+0.188*($T13-$I13/10)+0.161*($AA13-$R13/10)-0.131*$F13+4.5) -> 2.62428 | AU13: =IF(OR($E13="",$F13=""),"",IF($F13/$E13^(1/3)>=40.75,0.732*($F13/$E13^(1/3))-28.58,IF($F13/$E13^(1/3)>=38.25,0.463*($F13/$E13^(1/3))-17.63,0.1))) -> 3.9861124 | AV13: =IF(OR($AS13="",$AT13="",$AU13=""),"",IF(AND($AT13>=$AS13,$AT13>=$AU13),"Mesomorfo dominante",IF(AND($AU13>=$AS13,$AU13>=$AT13),"Ectomorfo dominante","Endomorfo dominante"))) -> Ectomorfo dominante
A14: 46034 | B14: Felipe Andrade Rocha | C14: Pré-temporada | D14: Comissão técnica | E14: 78 | F14: 184 | G14: 96 | H14: 190.2 | I14: 8.7 | J14: 12.2 | K14: 3.3 | L14: 6 | M14: 8.9 | N14: 13.7 | O14: 8.8 | P14: 15.6 | Q14: 12 | R14: 7.1 | S14: 34.3 | T14: 35.3 | U14: 29.9 | V14: 96.8 | W14: 85.7 | X14: 84 | Y14: 95.4 | Z14: 61.5 | AA14: 40.6 | AB14: 18.7 | AC14: 43.6 | AD14: 28.3 | AE14: 7.1 | AF14: 10.3 | AG14: =IFERROR(DATEDIF(INDEX(Cadastro!$D$8:$D$47,MATCH($B14,Cadastro!$B$8:$B$47,0)),$A14,"Y"),"") -> 22 | AH14: =IF(COUNT($I14,$K14,$J14,$N14)<4,"",$I14+$K14+$J14+$N14) -> 37.9 | AI14: =IF(COUNT($L14,$M14,$I14,$J14,$P14,$N14,$Q14)<7,"",$L14+$M14+$I14+$J14+$P14+$N14+$Q14) -> 77.1 | AJ14: =IF(COUNT($I14,$J14,$K14,$O14,$P14,$Q14,$R14,$N14)<8,"",$I14+$J14+$K14+$O14+$P14+$Q14+$R14+$N14) -> 81.4 | AK14: =IF(OR($AI14="",$AG14=""),"",IF(IFERROR(INDEX(Cadastro!$F$8:$F$47,MATCH($B14,Cadastro!$B$8:$B$47,0)),"")="Feminino",1.097-0.00046971*$AI14+0.00000056*$AI14^2-0.00012828*$AG14,1.112-0.00043499*$AI14+0.00000055*$AI14^2-0.00028826*$AG14)) -> 1.07539 | AL14: =IF(OR($AK14="",$AK14=0),"",495/$AK14-450) -> 10.298134 | AM14: =IF(OR($AL14="",$E14=""),"",$E14*$AL14/100) -> 8.0325449 | AN14: =IF(OR($AM14="",$E14=""),"",$E14-$AM14) -> 69.967455 | AO14: =IFERROR($E14/($F14/100)^2,"") -> 23.038752 | AP14: =IFERROR($G14/$F14*100,"") -> 52.173913 | AQ14: =IFERROR($W14/$F14,"") -> 0.46576087 | AR14: =IF(OR($S14="",$I14=""),"",($S14-PI()*$I14/10)^2/(4*PI())-IF(IFERROR(INDEX(Cadastro!$F$8:$F$47,MATCH($B14,Cadastro!$B$8:$B$47,0)),"")="Feminino",6.5,10)) -> 69.296067 | AS14: =IF(OR($I14="",$J14="",$O14="",$F14=""),"",-0.7182+0.1451*(($I14+$J14+$O14)*(170.18/$F14))-0.00068*(($I14+$J14+$O14)*(170.18/$F14))^2+0.0000014*(($I14+$J14+$O14)*(170.18/$F14))^3) -> 2.7835081 | AT14: =IF(OR($AE14="",$AF14="",$T14="",$AA14="",$F14=""),"",0.858*$AE14+0.601*$AF14+0.188*($T14-$I14/10)+0.161*($AA14-$R14/10)-0.131*$F14+4.5) -> 5.57323 | AU14: =IF(OR($E14="",$F14=""),"",IF($F14/$E14^(1/3)>=40.75,0.732*($F14/$E14^(1/3))-28.58,IF($F14/$E14^(1/3)>=38.25,0.463*($F14/$E14^(1/3))-17.63,0.1))) -> 2.9432295 | AV14: =IF(OR($AS14="",$AT14="",$AU14=""),"",IF(AND($AT14>=$AS14,$AT14>=$AU14),"Mesomorfo dominante",IF(AND($AU14>=$AS14,$AU14>=$AT14),"Ectomorfo dominante","Endomorfo dominante"))) -> Mesomorfo dominante
A15: 46034 | B15: Gustavo Peixoto Maia | C15: Pré-temporada | D15: Comissão técnica | E15: 91 | F15: 199 | G15: 103.9 | H15: 202.9 | I15: 9.1 | J15: 12.4 | K15: 5.2 | L15: 7.9 | M15: 8.8 | N15: 9.4 | O15: 9 | P15: 12.1 | Q15: 13.9 | R15: 9.5 | S15: 32.6 | T15: 33.5 | U15: 29.2 | V15: 99 | W15: 83.3 | X15: 83.2 | Y15: 99.8 | Z15: 56.4 | AA15: 40.5 | AB15: 18 | AC15: 42.5 | AD15: 28.7 | AE15: 7.2 | AF15: 10.2 | AG15: =IFERROR(DATEDIF(INDEX(Cadastro!$D$8:$D$47,MATCH($B15,Cadastro!$B$8:$B$47,0)),$A15,"Y"),"") -> 28 | AH15: =IF(COUNT($I15,$K15,$J15,$N15)<4,"",$I15+$K15+$J15+$N15) -> 36.1 | AI15: =IF(COUNT($L15,$M15,$I15,$J15,$P15,$N15,$Q15)<7,"",$L15+$M15+$I15+$J15+$P15+$N15+$Q15) -> 73.6 | AJ15: =IF(COUNT($I15,$J15,$K15,$O15,$P15,$Q15,$R15,$N15)<8,"",$I15+$J15+$K15+$O15+$P15+$Q15+$R15+$N15) -> 80.6 | AK15: =IF(OR($AI15="",$AG15=""),"",IF(IFERROR(INDEX(Cadastro!$F$8:$F$47,MATCH($B15,Cadastro!$B$8:$B$47,0)),"")="Feminino",1.097-0.00046971*$AI15+0.00000056*$AI15^2-0.00012828*$AG15,1.112-0.00043499*$AI15+0.00000055*$AI15^2-0.00028826*$AG15)) -> 1.0748928 | AL15: =IF(OR($AK15="",$AK15=0),"",495/$AK15-450) -> 10.511046 | AM15: =IF(OR($AL15="",$E15=""),"",$E15*$AL15/100) -> 9.5650516 | AN15: =IF(OR($AM15="",$E15=""),"",$E15-$AM15) -> 81.434948 | AO15: =IFERROR($E15/($F15/100)^2,"") -> 22.979218 | AP15: =IFERROR($G15/$F15*100,"") -> 52.211055 | AQ15: =IFERROR($W15/$F15,"") -> 0.41859296 | AR15: =IF(OR($S15="",$I15=""),"",($S15-PI()*$I15/10)^2/(4*PI())-IF(IFERROR(INDEX(Cadastro!$F$8:$F$47,MATCH($B15,Cadastro!$B$8:$B$47,0)),"")="Feminino",6.5,10)) -> 60.389142 | AS15: =IF(OR($I15="",$J15="",$O15="",$F15=""),"",-0.7182+0.1451*(($I15+$J15+$O15)*(170.18/$F15))-0.00068*(($I15+$J15+$O15)*(170.18/$F15))^2+0.0000014*(($I15+$J15+$O15)*(170.18/$F15))^3) -> 2.6286513 | AT15: =IF(OR($AE15="",$AF15="",$T15="",$AA15="",$F15=""),"",0.858*$AE15+0.601*$AF15+0.188*($T15-$I15/10)+0.161*($AA15-$R15/10)-0.131*$F15+4.5) -> 3.23327 | AU15: =IF(OR($E15="",$F15=""),"",IF($F15/$E15^(1/3)>=40.75,0.732*($F15/$E15^(1/3))-28.58,IF($F15/$E15^(1/3)>=38.25,0.463*($F15/$E15^(1/3))-17.63,0.1))) -> 3.8054816 | AV15: =IF(OR($AS15="",$AT15="",$AU15=""),"",IF(AND($AT15>=$AS15,$AT15>=$AU15),"Mesomorfo dominante",IF(AND($AU15>=$AS15,$AU15>=$AT15),"Ectomorfo dominante","Endomorfo dominante"))) -> Ectomorfo dominante
A16: 46034 | B16: Vinícius Barreto Duarte | C16: Pré-temporada | D16: Comissão técnica | E16: 84 | F16: 192 | G16: 100.2 | H16: 196.9 | I16: 11 | J16: 9.1 | K16: 3.9 | L16: 6.2 | M16: 7.2 | N16: 13.3 | O16: 6.3 | P16: 13.8 | Q16: 12.9 | R16: 6.2 | S16: 31.1 | T16: 33 | U16: 27.9 | V16: 104.8 | W16: 83 | X16: 87.1 | Y16: 101.2 | Z16: 55.4 | AA16: 40.5 | AB16: 18.2 | AC16: 44.4 | AD16: 28.1 | AE16: 7.4 | AF16: 9.6 | AG16: =IFERROR(DATEDIF(INDEX(Cadastro!$D$8:$D$47,MATCH($B16,Cadastro!$B$8:$B$47,0)),$A16,"Y"),"") -> 23 | AH16: =IF(COUNT($I16,$K16,$J16,$N16)<4,"",$I16+$K16+$J16+$N16) -> 37.3 | AI16: =IF(COUNT($L16,$M16,$I16,$J16,$P16,$N16,$Q16)<7,"",$L16+$M16+$I16+$J16+$P16+$N16+$Q16) -> 73.5 | AJ16: =IF(COUNT($I16,$J16,$K16,$O16,$P16,$Q16,$R16,$N16)<8,"",$I16+$J16+$K16+$O16+$P16+$Q16+$R16+$N16) -> 76.5 | AK16: =IF(OR($AI16="",$AG16=""),"",IF(IFERROR(INDEX(Cadastro!$F$8:$F$47,MATCH($B16,Cadastro!$B$8:$B$47,0)),"")="Feminino",1.097-0.00046971*$AI16+0.00000056*$AI16^2-0.00012828*$AG16,1.112-0.00043499*$AI16+0.00000055*$AI16^2-0.00028826*$AG16)) -> 1.0763695 | AL16: =IF(OR($AK16="",$AK16=0),"",495/$AK16-450) -> 9.8792547 | AM16: =IF(OR($AL16="",$E16=""),"",$E16*$AL16/100) -> 8.298574 | AN16: =IF(OR($AM16="",$E16=""),"",$E16-$AM16) -> 75.701426 | AO16: =IFERROR($E16/($F16/100)^2,"") -> 22.786458 | AP16: =IFERROR($G16/$F16*100,"") -> 52.1875 | AQ16: =IFERROR($W16/$F16,"") -> 0.43229167 | AR16: =IF(OR($S16="",$I16=""),"",($S16-PI()*$I16/10)^2/(4*PI())-IF(IFERROR(INDEX(Cadastro!$F$8:$F$47,MATCH($B16,Cadastro!$B$8:$B$47,0)),"")="Feminino",6.5,10)) -> 50.813458 | AS16: =IF(OR($I16="",$J16="",$O16="",$F16=""),"",-0.7182+0.1451*(($I16+$J16+$O16)*(170.18/$F16))-0.00068*(($I16+$J16+$O16)*(170.18/$F16))^2+0.0000014*(($I16+$J16+$O16)*(170.18/$F16))^3) -> 2.3227084 | AT16: =IF(OR($AE16="",$AF16="",$T16="",$AA16="",$F16=""),"",0.858*$AE16+0.601*$AF16+0.188*($T16-$I16/10)+0.161*($AA16-$R16/10)-0.131*$F16+4.5) -> 3.88468 | AU16: =IF(OR($E16="",$F16=""),"",IF($F16/$E16^(1/3)>=40.75,0.732*($F16/$E16^(1/3))-28.58,IF($F16/$E16^(1/3)>=38.25,0.463*($F16/$E16^(1/3))-17.63,0.1))) -> 3.5111944 | AV16: =IF(OR($AS16="",$AT16="",$AU16=""),"",IF(AND($AT16>=$AS16,$AT16>=$AU16),"Mesomorfo dominante",IF(AND($AU16>=$AS16,$AU16>=$AT16),"Ectomorfo dominante","Endomorfo dominante"))) -> Mesomorfo dominante
A17: 46034 | B17: André Luiz Sampaio | C17: Pré-temporada | D17: Comissão técnica | E17: 97 | F17: 201 | G17: 104.9 | H17: 206 | I17: 10.9 | J17: 12.2 | K17: 4 | L17: 5.3 | M17: 7.4 | N17: 8.5 | O17: 6.5 | P17: 16.4 | Q17: 12.1 | R17: 9.1 | S17: 33 | T17: 33.3 | U17: 28.2 | V17: 104.1 | W17: 81.8 | X17: 86.4 | Y17: 96.8 | Z17: 61 | AA17: 40.6 | AB17: 17.9 | AC17: 44.1 | AD17: 27.5 | AE17: 7.7 | AF17: 9.9 | AG17: =IFERROR(DATEDIF(INDEX(Cadastro!$D$8:$D$47,MATCH($B17,Cadastro!$B$8:$B$47,0)),$A17,"Y"),"") -> 31 | AH17: =IF(COUNT($I17,$K17,$J17,$N17)<4,"",$I17+$K17+$J17+$N17) -> 35.6 | AI17: =IF(COUNT($L17,$M17,$I17,$J17,$P17,$N17,$Q17)<7,"",$L17+$M17+$I17+$J17+$P17+$N17+$Q17) -> 72.8 | AJ17: =IF(COUNT($I17,$J17,$K17,$O17,$P17,$Q17,$R17,$N17)<8,"",$I17+$J17+$K17+$O17+$P17+$Q17+$R17+$N17) -> 79.7 | AK17: =IF(OR($AI17="",$AG17=""),"",IF(IFERROR(INDEX(Cadastro!$F$8:$F$47,MATCH($B17,Cadastro!$B$8:$B$47,0)),"")="Feminino",1.097-0.00046971*$AI17+0.00000056*$AI17^2-0.00012828*$AG17,1.112-0.00043499*$AI17+0.00000055*$AI17^2-0.00028826*$AG17)) -> 1.0743116 | AL17: =IF(OR($AK17="",$AK17=0),"",495/$AK17-450) -> 10.760183 | AM17: =IF(OR($AL17="",$E17=""),"",$E17*$AL17/100) -> 10.437377 | AN17: =IF(OR($AM17="",$E17=""),"",$E17-$AM17) -> 86.562623 | AO17: =IFERROR($E17/($F17/100)^2,"") -> 24.009307 | AP17: =IFERROR($G17/$F17*100,"") -> 52.189055 | AQ17: =IFERROR($W17/$F17,"") -> 0.40696517 | AR17: =IF(OR($S17="",$I17=""),"",($S17-PI()*$I17/10)^2/(4*PI())-IF(IFERROR(INDEX(Cadastro!$F$8:$F$47,MATCH($B17,Cadastro!$B$8:$B$47,0)),"")="Feminino",6.5,10)) -> 59.607998 | AS17: =IF(OR($I17="",$J17="",$O17="",$F17=""),"",-0.7182+0.1451*(($I17+$J17+$O17)*(170.18/$F17))-0.00068*(($I17+$J17+$O17)*(170.18/$F17))^2+0.0000014*(($I17+$J17+$O17)*(170.18/$F17))^3) -> 2.513148 | AT17: =IF(OR($AE17="",$AF17="",$T17="",$AA17="",$F17=""),"",0.858*$AE17+0.601*$AF17+0.188*($T17-$I17/10)+0.161*($AA17-$R17/10)-0.131*$F17+4.5) -> 3.17107 | AU17: =IF(OR($E17="",$F17=""),"",IF($F17/$E17^(1/3)>=40.75,0.732*($F17/$E17^(1/3))-28.58,IF($F17/$E17^(1/3)>=38.25,0.463*($F17/$E17^(1/3))-17.63,0.1))) -> 3.4421062 | AV17: =IF(OR($AS17="",$AT17="",$AU17=""),"",IF(AND($AT17>=$AS17,$AT17>=$AU17),"Mesomorfo dominante",IF(AND($AU17>=$AS17,$AU17>=$AT17),"Ectomorfo dominante","Endomorfo dominante"))) -> Ectomorfo dominante
