Workbook

Sheet Início
A1: PLANILHA DE CONTROLE E PRESCRIÇÃO DE TREINAMENTO • VOLEIBOL
A2: Periodização Macrociclo → Mesociclo → Microciclo → Sessão | Controle de carga por PSE da sessão, ACWR, Monotonia/Strain e Wellness
B4: COMO USAR — PASSO A PASSO
B5: 1. Listas | C5: Confira/ajuste as opções de todos os menus suspensos (posições, categorias, tipos de sessão, etc.).
B6: 2. Cadastro | C6: Cadastre os atletas. O nome cadastrado alimenta TODAS as demais abas automaticamente.
B7: 3. Macrociclo | C7: Defina a temporada (datas, objetivo) e divida-a em mesociclos com volume/intensidade previstos.
B8: 4. Mesociclo | C8: Escolha um mesociclo no menu e detalhe os microciclos (semanas), com carga prevista x realizada.
B9: 5. Microciclo | C9: Monte a semana: sessões por dia, duração, PSE prevista e distribuição de conteúdos.
B10: 6. Exercícios | C10: Biblioteca de exercícios. Já vem com 42 exercícios de voleibol — inclua os seus.
B11: 7. Prescrição | C11: PRESCREVA o treino: uma linha por exercício, com séries, repetições, carga, pausa e destinatário.
B12: 8. Carga (PSE) | C12: REGISTRE o realizado: duração x PSE = carga em UA. ACWR, aguda e crônica são calculados sozinhos.
B13: 9. Wellness | C13: Questionário diário (sono, estresse, fadiga, dor) → Índice de Hooper e classificação automática.
B14: 10. Presença | C14: Chamada por sessão, com % de presença por atleta calculado ao lado.
B15: 11. Testes | C15: Avaliações físicas periódicas (saltos, alcances, agilidade, sprint, flexibilidade).
B16: 12. Atleta | C16: ÁREA DO ATLETA: escolha o nome e ele vê o próprio perfil, cargas, monotonia e o treino prescrito.
B17: 13. Painel | C17: PAINEL INTERATIVO: indicadores e gráficos de toda a equipe, por semana e por atleta.
B19: LEGENDA DE CORES
B20: Célula de PREENCHIMENTO (azul sobre amarelo)
B21: Célula CALCULADA — não digite por cima
B22: Cabeçalho de tabela
B23: Alerta / risco elevado
B24: Atenção / monitorar
B25: Adequado / dentro da meta
B27: MÉTRICAS DE CONTROLE UTILIZADAS — DEFINIÇÕES E REFERÊNCIAS
B28: Carga Interna (UA) | C28: Duração da sessão (min) × PSE da sessão (escala 0–10, coletada ~30 min após o treino). Método da PSE da sessão de Foster et al. (2001), J Strength Cond Res.
B29: Carga Aguda (7 d) | C29: Soma da carga em UA dos últimos 7 dias do atleta (inclui o dia atual).
B30: Carga Crônica (28 d) | C30: Soma da carga dos últimos 28 dias ÷ 4 (média semanal), para ficar na mesma escala da aguda.
B31: ACWR | C31: Carga Aguda ÷ Carga Crônica. Faixas usadas na planilha: <0,80 subcarga | 0,80–1,30 zona ideal | 1,31–1,50 atenção | >1,50 risco elevado. Referência: Gabbett (2016), Br J Sports Med. Interpretar sempre junto do contexto e da clínica do atleta.
B32: Monotonia | C32: Média das cargas diárias da semana ÷ desvio-padrão dessas mesmas cargas (7 dias, dias de folga contam como zero). >2,0 indica semana monótona.
B33: Strain | C33: Carga semanal total × Monotonia. Picos de strain associam-se a maior risco de lesão/doença (Foster, 1998).
B34: Índice de Hooper | C34: Soma de 4 itens (qualidade do sono, estresse, fadiga e dor muscular), cada um de 1 = muito bom/ausente a 7 = muito ruim/máxima. Varia de 4 a 28; QUANTO MAIOR, PIOR. Referência: Hooper & Mackinnon (1995), Sports Med.
B35: Volume × Intensidade | C35: No Macrociclo, valores em % representam a proporção relativa planejada para cada mesociclo (ex.: 85% = volume alto).
B37: ATENÇÃO — DADOS DE EXEMPLO: a planilha vem preenchida com 12 atletas fictícios, um macrociclo modelo e registros de carga/wellness/presença apenas para demonstrar os cálculos e os gráficos. Apague esses dados (linhas marcadas como EXEMPLO) antes de usar com a sua equipe. As fórmulas permanecem intactas. AVISO: esta planilha é uma ferramenta de organização do treino. Não substitui avaliação médica nem fisioterápica; os indicadores de risco são apoio à decisão do técnico/preparador físico.

Sheet Cadastro
A1: CADASTRO DE ATLETAS
A2: Preencha as colunas em amarelo. As colunas cinza são calculadas. O nome digitado aqui aparece nos menus de todas as outras abas.
B4: Campos obrigatórios: Nome, Data de Nascimento, Estatura e Massa. Alcance em Pé = altura atingida em pé com o braço dominante estendido — é a base para calcular as impulsões.
A6: ID | B6: Nome Completo | C6: Data de Nasc. | D6: Idade | E6: Sexo | F6: Posição | G6: Categoria | H6: Nº Camisa | I6: Dominância | J6: Estatura (m) | K6: Massa (kg) | L6: IMC | M6: Envergadura (cm) | N6: Alcance em Pé (cm) | O6: Alcance de Ataque (cm) | P6: Alcance de Bloqueio (cm) | Q6: Impulsão de Ataque (cm) | R6: Impulsão de Bloqueio (cm) | S6: Entrada na Equipe | T6: Status | U6: Contato / Responsável | V6: Observações
A7: =IF($B7="","","ATL-"&TEXT(ROW()-6,"000")) | D7: =IFERROR(DATEDIF($C7,TODAY(),"Y"),"") -> 126 | L7: =IFERROR(ROUND($K7/$J7^2,1),"") | Q7: =IF(OR($O7="",$N7=""),"",$O7-$N7) | R7: =IF(OR($P7="",$N7=""),"",$P7-$N7) | V7: ← primeira linha: preencha aqui
A8: =IF($B8="","","ATL-"&TEXT(ROW()-6,"000")) | D8: =IFERROR(DATEDIF($C8,TODAY(),"Y"),"") -> 126 | L8: =IFERROR(ROUND($K8/$J8^2,1),"") | Q8: =IF(OR($O8="",$N8=""),"",$O8-$N8) | R8: =IF(OR($P8="",$N8=""),"",$P8-$N8)
A9: =IF($B9="","","ATL-"&TEXT(ROW()-6,"000")) | D9: =IFERROR(DATEDIF($C9,TODAY(),"Y"),"") -> 126 | L9: =IFERROR(ROUND($K9/$J9^2,1),"") | Q9: =IF(OR($O9="",$N9=""),"",$O9-$N9) | R9: =IF(OR($P9="",$N9=""),"",$P9-$N9)
A10: =IF($B10="","","ATL-"&TEXT(ROW()-6,"000")) | D10: =IFERROR(DATEDIF($C10,TODAY(),"Y"),"") -> 126 | L10: =IFERROR(ROUND($K10/$J10^2,1),"") | Q10: =IF(OR($O10="",$N10=""),"",$O10-$N10) | R10: =IF(OR($P10="",$N10=""),"",$P10-$N10)
A11: =IF($B11="","","ATL-"&TEXT(ROW()-6,"000")) | D11: =IFERROR(DATEDIF($C11,TODAY(),"Y"),"") -> 126 | L11: =IFERROR(ROUND($K11/$J11^2,1),"") | Q11: =IF(OR($O11="",$N11=""),"",$O11-$N11) | R11: =IF(OR($P11="",$N11=""),"",$P11-$N11)
A12: =IF($B12="","","ATL-"&TEXT(ROW()-6,"000")) | D12: =IFERROR(DATEDIF($C12,TODAY(),"Y"),"") -> 126 | L12: =IFERROR(ROUND($K12/$J12^2,1),"") | Q12: =IF(OR($O12="",$N12=""),"",$O12-$N12) | R12: =IF(OR($P12="",$N12=""),"",$P12-$N12)
A13: =IF($B13="","","ATL-"&TEXT(ROW()-6,"000")) | D13: =IFERROR(DATEDIF($C13,TODAY(),"Y"),"") -> 126 | L13: =IFERROR(ROUND($K13/$J13^2,1),"") | Q13: =IF(OR($O13="",$N13=""),"",$O13-$N13) | R13: =IF(OR($P13="",$N13=""),"",$P13-$N13)
A14: =IF($B14="","","ATL-"&TEXT(ROW()-6,"000")) | D14: =IFERROR(DATEDIF($C14,TODAY(),"Y"),"") -> 126 | L14: =IFERROR(ROUND($K14/$J14^2,1),"") | Q14: =IF(OR($O14="",$N14=""),"",$O14-$N14) | R14: =IF(OR($P14="",$N14=""),"",$P14-$N14)
A15: =IF($B15="","","ATL-"&TEXT(ROW()-6,"000")) | D15: =IFERROR(DATEDIF($C15,TODAY(),"Y"),"") -> 126 | L15: =IFERROR(ROUND($K15/$J15^2,1),"") | Q15: =IF(OR($O15="",$N15=""),"",$O15-$N15) | R15: =IF(OR($P15="",$N15=""),"",$P15-$N15)
A16: =IF($B16="","","ATL-"&TEXT(ROW()-6,"000")) | D16: =IFERROR(DATEDIF($C16,TODAY(),"Y"),"") -> 126 | L16: =IFERROR(ROUND($K16/$J16^2,1),"") | Q16: =IF(OR($O16="",$N16=""),"",$O16-$N16) | R16: =IF(OR($P16="",$N16=""),"",$P16-$N16)
A17: =IF($B17="","","ATL-"&TEXT(ROW()-6,"000")) | D17: =IFERROR(DATEDIF($C17,TODAY(),"Y"),"") -> 126 | L17: =IFERROR(ROUND($K17/$J17^2,1),"") | Q17: =IF(OR($O17="",$N17=""),"",$O17-$N17) | R17: =IF(OR($P17="",$N17=""),"",$P17-$N17)
A18: =IF($B18="","","ATL-"&TEXT(ROW()-6,"000")) | D18: =IFERROR(DATEDIF($C18,TODAY(),"Y"),"") -> 126 | L18: =IFERROR(ROUND($K18/$J18^2,1),"") | Q18: =IF(OR($O18="",$N18=""),"",$O18-$N18) | R18: =IF(OR($P18="",$N18=""),"",$P18-$N18)
A19: =IF($B19="","","ATL-"&TEXT(ROW()-6,"000")) | D19: =IFERROR(DATEDIF($C19,TODAY(),"Y"),"") -> 126 | L19: =IFERROR(ROUND($K19/$J19^2,1),"") | Q19: =IF(OR($O19="",$N19=""),"",$O19-$N19) | R19: =IF(OR($P19="",$N19=""),"",$P19-$N19)
... A66: =IF($B66="","","ATL-"&TEXT(ROW()-6,"000")) | D66: =IFERROR(DATEDIF($C66,TODAY(),"Y"),"") -> 126 | L66: =IFERROR(ROUND($K66/$J66^2,1),"") | Q66: =IF(OR($O66="",$N66=""),"",$O66-$N66) | R66: =IF(OR($P66="",$N66=""),"",$P66-$N66)

Sheet Exercícios
A1: BIBLIOTECA DE EXERCÍCIOS
A2: Cada exercício cadastrado aqui fica disponível no menu suspenso da aba Prescrição, que puxa automaticamente categoria, fundamento e capacidade física.
A6: ID | B6: Exercício | C6: Categoria | D6: Fundamento | E6: Capacidade Física | F6: Objetivo | G6: Descrição / Execução | H6: Material | I6: Nº de Atletas | J6: Duração Sug. (min) | K6: Intensidade Sug. | L6: PSE Sug. | M6: Nível | N6: Link de Vídeo
A7: =IF($B7="","","EX-"&TEXT(ROW()-6,"000")) -> EX-001 | B7: Saque flutuante de apoio | C7: Técnico | D7: Saque | E7: Coordenação | F7: Precisão e constância do saque flutuante | G7: Séries de 10 saques por zona alvo (1, 5 e 6). Contato firme no centro da bola, sem rotação, braço freado no impacto. | H7: Bolas, cones/alvos | I7: 1 | J7: 12 | K7: Moderada | L7: 4 | M7: Iniciante
A8: =IF($B8="","","EX-"&TEXT(ROW()-6,"000")) -> EX-002 | B8: Saque viagem no fundo (jump float) | C8: Técnico | D8: Saque | E8: Coordenação | F8: Saque flutuante com salto e maior velocidade | G8: Passada de 2–3 tempos, salto vertical, contato seco. 3 blocos de 8 saques com alvo no fundo da quadra. | H8: Bolas | I8: 1 | J8: 12 | K8: Alta | L8: 5 | M8: Intermediário
A9: =IF($B9="","","EX-"&TEXT(ROW()-6,"000")) -> EX-003 | B9: Saque potente com salto | C9: Técnico | D9: Saque | E9: Força Explosiva/Potência | F9: Velocidade e agressividade no saque | G9: 4 séries de 6 saques em potência máxima, alternando zona 1 e zona 5. Pausa completa entre séries. | H9: Bolas | I9: 1 | J9: 15 | K9: Muito Alta | L9: 7 | M9: Avançado
A10: =IF($B10="","","EX-"&TEXT(ROW()-6,"000")) -> EX-004 | B10: Recepção em duplas com bola dirigida | C10: Técnico | D10: Recepção (Passe) | E10: Coordenação | F10: Plataforma estável e passe ao alvo | G10: Técnico lança bolas alternadas; atleta recebe para o alvo em zona 2/3. 3 x 15 repetições. | H10: Bolas, alvo/cesto | I10: 2 | J10: 12 | K10: Moderada | L10: 4 | M10: Iniciante
A11: =IF($B11="","","EX-"&TEXT(ROW()-6,"000")) -> EX-005 | B11: Recepção de saque em sistema de 2 passadores | C11: Técnico | D11: Recepção (Passe) | E11: Coordenação | F11: Leitura de trajetória e responsabilidade de zona | G11: Sacador real do outro lado. Passadores em L; 20 saques por rodízio, meta de 70% de passes A/B. | H11: Bolas, rede | I11: 4 | J11: 20 | K11: Alta | L11: 6 | M11: Intermediário
A12: =IF($B12="","","EX-"&TEXT(ROW()-6,"000")) -> EX-006 | B12: Manchete de deslocamento lateral (leque) | C12: Técnico | D12: Recepção (Passe) | E12: Agilidade/COD | F12: Deslocamento e recepção fora da base | G12: Bolas alternadas à direita e à esquerda; deslocamento em passo lateral e retorno à base. 4 x 30 s. | H12: Bolas | I12: 1 | J12: 10 | K12: Alta | L12: 6 | M12: Intermediário
A13: =IF($B13="","","EX-"&TEXT(ROW()-6,"000")) -> EX-007 | B13: Levantamento em suspensão contra a parede | C13: Técnico | D13: Levantamento | E13: Coordenação | F13: Consistência do toque e ação simétrica das mãos | G13: 3 x 30 toques contra a parede a 3 m, mantendo a bola sem rotação. | H13: Bola, parede | I13: 1 | J13: 8 | K13: Baixa | L13: 3 | M13: Iniciante
A14: =IF($B14="","","EX-"&TEXT(ROW()-6,"000")) -> EX-008 | B14: Levantamento em rede com alvos | C14: Técnico | D14: Levantamento | E14: Coordenação | F14: Precisão de bola alta, rápida e de fundo | G14: Levantador recebe passe do técnico e distribui para alvos em P4, P2 e Pipe. 5 x 12 levantamentos. | H14: Bolas, aros/alvos | I14: 2 | J14: 18 | K14: Moderada | L14: 5 | M14: Intermediário
A15: =IF($B15="","","EX-"&TEXT(ROW()-6,"000")) -> EX-009 | B15: Levantamento invertido (costas) | C15: Técnico | D15: Levantamento | E15: Coordenação | F15: Domínio do levantamento para trás sem sinalizar | G15: 3 x 15 levantamentos de costas para P2 com o técnico corrigindo a extensão de quadril. | H15: Bolas | I15: 2 | J15: 12 | K15: Moderada | L15: 5 | M15: Avançado
A16: =IF($B16="","","EX-"&TEXT(ROW()-6,"000")) -> EX-010 | B16: Ataque de bola alta pela ponta (P4) | C16: Técnico | D16: Ataque | E16: Força Explosiva/Potência | F16: Ritmo de aproximação e ataque em bola alta | G16: 4 x 10 ataques com levantador real. Foco na passada de 3 tempos e no braço em arco. | H16: Bolas, rede | I16: 3 | J16: 18 | K16: Alta | L16: 6 | M16: Intermediário
A17: =IF($B17="","","EX-"&TEXT(ROW()-6,"000")) -> EX-011 | B17: Ataque de primeiro tempo (P3) | C17: Técnico | D17: Ataque | E17: Velocidade | F17: Sincronia central x levantador | G17: 4 x 8 ataques de bola rápida, variando o ponto de contato ao longo da rede. | H17: Bolas, rede | I17: 3 | J17: 15 | K17: Alta | L17: 6 | M17: Avançado
A18: =IF($B18="","","EX-"&TEXT(ROW()-6,"000")) -> EX-012 | B18: Ataque de fundo (Pipe / P6) | C18: Técnico | D18: Ataque | E18: Força Explosiva/Potência | F18: Ataque a partir da linha de 3 m | G18: 3 x 10 ataques de fundo saindo da recepção. Atenção à marca dos 3 m. | H18: Bolas, rede | I18: 3 | J18: 15 | K18: Alta | L18: 6 | M18: Avançado
... A48: =IF($B48="","","EX-"&TEXT(ROW()-6,"000")) -> EX-042 | B48: Reação visual com estímulo do técnico | C48: Cognitivo/Visual | D48: Defesa | E48: Coordenação | F48: Tempo de reação e leitura antecipatória | G48: Técnico sinaliza a direção no último instante; atleta desloca e defende. 5 x 30 s. | H48: Bolas, sinalizadores | I48: 1 | J48: 10 | K48: Alta | L48: 6 | M48: Intermediário
A49: =IF($B49="","","EX-"&TEXT(ROW()-6,"000"))
A50: =IF($B50="","","EX-"&TEXT(ROW()-6,"000"))
A51: =IF($B51="","","EX-"&TEXT(ROW()-6,"000"))
A52: =IF($B52="","","EX-"&TEXT(ROW()-6,"000"))
A53: =IF($B53="","","EX-"&TEXT(ROW()-6,"000"))
A54: =IF($B54="","","EX-"&TEXT(ROW()-6,"000"))
A55: =IF($B55="","","EX-"&TEXT(ROW()-6,"000"))
A56: =IF($B56="","","EX-"&TEXT(ROW()-6,"000"))
A57: =IF($B57="","","EX-"&TEXT(ROW()-6,"000"))
A58: =IF($B58="","","EX-"&TEXT(ROW()-6,"000"))
A59: =IF($B59="","","EX-"&TEXT(ROW()-6,"000"))
A60: =IF($B60="","","EX-"&TEXT(ROW()-6,"000"))
... A206: =IF($B206="","","EX-"&TEXT(ROW()-6,"000"))

Sheet Macrociclo
A1: MACROCICLO — PLANEJAMENTO DA TEMPORADA
A2: Defina o período total e divida-o em mesociclos. A Data de Início (C11) é a referência de TODA a numeração de semanas da planilha.
B4: IDENTIFICAÇÃO DO MACROCICLO
B6: Temporada / Época
B7: Equipe / Clube
B8: Categoria
B9: Técnico Responsável
B10: Preparador Físico
B11: Data de Início | C11: 46027
B12: Data de Término | C12: 46355
B13: Duração (semanas) | C13: =IFERROR(ROUNDUP(($C$12-$C$11+1)/7,0),"") -> 47
B14: Objetivo Principal
B15: Competição-Alvo
A17: DIVISÃO EM MESOCICLOS
A18: Nº | B18: Mesociclo | C18: Período | D18: Data Início | E18: Data Fim | F18: Semanas | G18: Semana Inicial | H18: Volume (%) | I18: Intensidade (%) | J18: Ênfase Física | K18: Ênfase Técnica | L18: Ênfase Tática | M18: Carga-Alvo Semanal (UA) | N18: Competições no Período | O18: Situação
A19: =IF($B19="","",ROW()-18) | F19: =IF(OR($D19="",$E19=""),0,ROUNDUP(($E19-$D19+1)/7,0)) -> 0 | G19: =IF(OR($D19="",$C$11=""),0,INT(($D19-$C$11)/7)+1) -> 0
A20: =IF($B20="","",ROW()-18) | F20: =IF(OR($D20="",$E20=""),0,ROUNDUP(($E20-$D20+1)/7,0)) -> 0 | G20: =IF(OR($D20="",$C$11=""),0,INT(($D20-$C$11)/7)+1) -> 0
A21: =IF($B21="","",ROW()-18) | F21: =IF(OR($D21="",$E21=""),0,ROUNDUP(($E21-$D21+1)/7,0)) -> 0 | G21: =IF(OR($D21="",$C$11=""),0,INT(($D21-$C$11)/7)+1) -> 0
A22: =IF($B22="","",ROW()-18) | F22: =IF(OR($D22="",$E22=""),0,ROUNDUP(($E22-$D22+1)/7,0)) -> 0 | G22: =IF(OR($D22="",$C$11=""),0,INT(($D22-$C$11)/7)+1) -> 0
A23: =IF($B23="","",ROW()-18) | F23: =IF(OR($D23="",$E23=""),0,ROUNDUP(($E23-$D23+1)/7,0)) -> 0 | G23: =IF(OR($D23="",$C$11=""),0,INT(($D23-$C$11)/7)+1) -> 0
A24: =IF($B24="","",ROW()-18) | F24: =IF(OR($D24="",$E24=""),0,ROUNDUP(($E24-$D24+1)/7,0)) -> 0 | G24: =IF(OR($D24="",$C$11=""),0,INT(($D24-$C$11)/7)+1) -> 0
A25: =IF($B25="","",ROW()-18) | F25: =IF(OR($D25="",$E25=""),0,ROUNDUP(($E25-$D25+1)/7,0)) -> 0 | G25: =IF(OR($D25="",$C$11=""),0,INT(($D25-$C$11)/7)+1) -> 0
A26: =IF($B26="","",ROW()-18) | F26: =IF(OR($D26="",$E26=""),0,ROUNDUP(($E26-$D26+1)/7,0)) -> 0 | G26: =IF(OR($D26="",$C$11=""),0,INT(($D26-$C$11)/7)+1) -> 0
A27: =IF($B27="","",ROW()-18) | F27: =IF(OR($D27="",$E27=""),0,ROUNDUP(($E27-$D27+1)/7,0)) -> 0 | G27: =IF(OR($D27="",$C$11=""),0,INT(($D27-$C$11)/7)+1) -> 0
A28: =IF($B28="","",ROW()-18) | F28: =IF(OR($D28="",$E28=""),0,ROUNDUP(($E28-$D28+1)/7,0)) -> 0 | G28: =IF(OR($D28="",$C$11=""),0,INT(($D28-$C$11)/7)+1) -> 0
A29: =IF($B29="","",ROW()-18) | F29: =IF(OR($D29="",$E29=""),0,ROUNDUP(($E29-$D29+1)/7,0)) -> 0 | G29: =IF(OR($D29="",$C$11=""),0,INT(($D29-$C$11)/7)+1) -> 0
A30: =IF($B30="","",ROW()-18) | F30: =IF(OR($D30="",$E30=""),0,ROUNDUP(($E30-$D30+1)/7,0)) -> 0 | G30: =IF(OR($D30="",$C$11=""),0,INT(($D30-$C$11)/7)+1) -> 0
B31: TOTAL / MÉDIA | F31: =SUM(F19:F30) -> 0 | H31: =IFERROR(AVERAGE(H19:H30),"") | I31: =IFERROR(AVERAGE(I19:I30),"") | M31: =IFERROR(SUMPRODUCT($F19:$F30,$M19:$M30),"") -> 0
B32: Confira: a soma de semanas dos mesociclos deve bater com a Duração (semanas) em C13. A Carga-Alvo total é a soma de (semanas × carga-alvo semanal) de cada mesociclo.

Sheet Mesociclo
A1: MESOCICLO — DETALHAMENTO EM MICROCICLOS
A2: Escolha o mesociclo no menu suspenso: os dados do planejamento são puxados do Macrociclo automaticamente.
B4: SELEÇÃO E RESUMO DO MESOCICLO
B6: Mesociclo selecionado
B8: Período | C8: =IFERROR(INDEX(Macrociclo!$C$19:$C$30,MATCH($C$6,Macrociclo!$B$19:$B$30,0)),"") | F8: Ênfase Física | G8: =IFERROR(INDEX(Macrociclo!$J$19:$J$30,MATCH($C$6,Macrociclo!$B$19:$B$30,0)),"")
B9: Data de Início | C9: =IFERROR(INDEX(Macrociclo!$D$19:$D$30,MATCH($C$6,Macrociclo!$B$19:$B$30,0)),"") | F9: Ênfase Técnica | G9: =IFERROR(INDEX(Macrociclo!$K$19:$K$30,MATCH($C$6,Macrociclo!$B$19:$B$30,0)),"")
B10: Data de Término | C10: =IFERROR(INDEX(Macrociclo!$E$19:$E$30,MATCH($C$6,Macrociclo!$B$19:$B$30,0)),"") | F10: Ênfase Tática | G10: =IFERROR(INDEX(Macrociclo!$L$19:$L$30,MATCH($C$6,Macrociclo!$B$19:$B$30,0)),"")
B11: Duração (semanas) | C11: =IFERROR(INDEX(Macrociclo!$F$19:$F$30,MATCH($C$6,Macrociclo!$B$19:$B$30,0)),"") | F11: Competições | G11: =IFERROR(INDEX(Macrociclo!$N$19:$N$30,MATCH($C$6,Macrociclo!$B$19:$B$30,0)),"")
B12: Semana Inicial no Macro | C12: =IFERROR(INDEX(Macrociclo!$G$19:$G$30,MATCH($C$6,Macrociclo!$B$19:$B$30,0)),"")
B13: Volume Planejado | C13: =IFERROR(INDEX(Macrociclo!$H$19:$H$30,MATCH($C$6,Macrociclo!$B$19:$B$30,0)),"")
B14: Intensidade Planejada | C14: =IFERROR(INDEX(Macrociclo!$I$19:$I$30,MATCH($C$6,Macrociclo!$B$19:$B$30,0)),"")
B15: Carga-Alvo Semanal (UA) | C15: =IFERROR(INDEX(Macrociclo!$M$19:$M$30,MATCH($C$6,Macrociclo!$B$19:$B$30,0)),"")
A17: MICROCICLOS DO MESOCICLO — PREVISTO × REALIZADO
A18: Nº | B18: Microciclo | C18: Tipo de Microciclo | D18: Data Início | E18: Data Fim | F18: Objetivo do Microciclo | G18: Semana nº | H18: Sessões Previstas | I18: Volume Previsto (min) | J18: PSE Média Prevista | K18: Carga Prevista (UA) | L18: % Cumprido | M18: Observações
A19: =IF($B19="","",ROW()-18) | G19: =IF(OR($D19="",Macrociclo!$C$11=""),0,INT(($D19-Macrociclo!$C$11)/7)+1) -> 0 | K19: =IF(OR($I19="",$J19=""),0,$I19*$J19) -> 0 | L19: =IF($K19=0,0,SUMIFS('Carga (PSE)'!$G$8:$G$1007,'Carga (PSE)'!$B$8:$B$1007,$G19)/MAX(1,COUNTIF(Cadastro!$T$7:$T$66,"Ativo"))/$K19) -> 0
A20: =IF($B20="","",ROW()-18) | G20: =IF(OR($D20="",Macrociclo!$C$11=""),0,INT(($D20-Macrociclo!$C$11)/7)+1) -> 0 | K20: =IF(OR($I20="",$J20=""),0,$I20*$J20) -> 0 | L20: =IF($K20=0,0,SUMIFS('Carga (PSE)'!$G$8:$G$1007,'Carga (PSE)'!$B$8:$B$1007,$G20)/MAX(1,COUNTIF(Cadastro!$T$7:$T$66,"Ativo"))/$K20) -> 0
A21: =IF($B21="","",ROW()-18) | G21: =IF(OR($D21="",Macrociclo!$C$11=""),0,INT(($D21-Macrociclo!$C$11)/7)+1) -> 0 | K21: =IF(OR($I21="",$J21=""),0,$I21*$J21) -> 0 | L21: =IF($K21=0,0,SUMIFS('Carga (PSE)'!$G$8:$G$1007,'Carga (PSE)'!$B$8:$B$1007,$G21)/MAX(1,COUNTIF(Cadastro!$T$7:$T$66,"Ativo"))/$K21) -> 0
A22: =IF($B22="","",ROW()-18) | G22: =IF(OR($D22="",Macrociclo!$C$11=""),0,INT(($D22-Macrociclo!$C$11)/7)+1) -> 0 | K22: =IF(OR($I22="",$J22=""),0,$I22*$J22) -> 0 | L22: =IF($K22=0,0,SUMIFS('Carga (PSE)'!$G$8:$G$1007,'Carga (PSE)'!$B$8:$B$1007,$G22)/MAX(1,COUNTIF(Cadastro!$T$7:$T$66,"Ativo"))/$K22) -> 0
A23: =IF($B23="","",ROW()-18) | G23: =IF(OR($D23="",Macrociclo!$C$11=""),0,INT(($D23-Macrociclo!$C$11)/7)+1) -> 0 | K23: =IF(OR($I23="",$J23=""),0,$I23*$J23) -> 0 | L23: =IF($K23=0,0,SUMIFS('Carga (PSE)'!$G$8:$G$1007,'Carga (PSE)'!$B$8:$B$1007,$G23)/MAX(1,COUNTIF(Cadastro!$T$7:$T$66,"Ativo"))/$K23) -> 0
A24: =IF($B24="","",ROW()-18) | G24: =IF(OR($D24="",Macrociclo!$C$11=""),0,INT(($D24-Macrociclo!$C$11)/7)+1) -> 0 | K24: =IF(OR($I24="",$J24=""),0,$I24*$J24) -> 0 | L24: =IF($K24=0,0,SUMIFS('Carga (PSE)'!$G$8:$G$1007,'Carga (PSE)'!$B$8:$B$1007,$G24)/MAX(1,COUNTIF(Cadastro!$T$7:$T$66,"Ativo"))/$K24) -> 0
A25: =IF($B25="","",ROW()-18) | G25: =IF(OR($D25="",Macrociclo!$C$11=""),0,INT(($D25-Macrociclo!$C$11)/7)+1) -> 0 | K25: =IF(OR($I25="",$J25=""),0,$I25*$J25) -> 0 | L25: =IF($K25=0,0,SUMIFS('Carga (PSE)'!$G$8:$G$1007,'Carga (PSE)'!$B$8:$B$1007,$G25)/MAX(1,COUNTIF(Cadastro!$T$7:$T$66,"Ativo"))/$K25) -> 0
A26: =IF($B26="","",ROW()-18) | G26: =IF(OR($D26="",Macrociclo!$C$11=""),0,INT(($D26-Macrociclo!$C$11)/7)+1) -> 0 | K26: =IF(OR($I26="",$J26=""),0,$I26*$J26) -> 0 | L26: =IF($K26=0,0,SUMIFS('Carga (PSE)'!$G$8:$G$1007,'Carga (PSE)'!$B$8:$B$1007,$G26)/MAX(1,COUNTIF(Cadastro!$T$7:$T$66,"Ativo"))/$K26) -> 0
A27: =IF($B27="","",ROW()-18) | G27: =IF(OR($D27="",Macrociclo!$C$11=""),0,INT(($D27-Macrociclo!$C$11)/7)+1) -> 0 | K27: =IF(OR($I27="",$J27=""),0,$I27*$J27) -> 0 | L27: =IF($K27=0,0,SUMIFS('Carga (PSE)'!$G$8:$G$1007,'Carga (PSE)'!$B$8:$B$1007,$G27)/MAX(1,COUNTIF(Cadastro!$T$7:$T$66,"Ativo"))/$K27) -> 0
A28: =IF($B28="","",ROW()-18) | G28: =IF(OR($D28="",Macrociclo!$C$11=""),0,INT(($D28-Macrociclo!$C$11)/7)+1) -> 0 | K28: =IF(OR($I28="",$J28=""),0,$I28*$J28) -> 0 | L28: =IF($K28=0,0,SUMIFS('Carga (PSE)'!$G$8:$G$1007,'Carga (PSE)'!$B$8:$B$1007,$G28)/MAX(1,COUNTIF(Cadastro!$T$7:$T$66,"Ativo"))/$K28) -> 0
A29: =IF($B29="","",ROW()-18) | G29: =IF(OR($D29="",Macrociclo!$C$11=""),0,INT(($D29-Macrociclo!$C$11)/7)+1) -> 0 | K29: =IF(OR($I29="",$J29=""),0,$I29*$J29) -> 0 | L29: =IF($K29=0,0,SUMIFS('Carga (PSE)'!$G$8:$G$1007,'Carga (PSE)'!$B$8:$B$1007,$G29)/MAX(1,COUNTIF(Cadastro!$T$7:$T$66,"Ativo"))/$K29) -> 0
A30: =IF($B30="","",ROW()-18) | G30: =IF(OR($D30="",Macrociclo!$C$11=""),0,INT(($D30-Macrociclo!$C$11)/7)+1) -> 0 | K30: =IF(OR($I30="",$J30=""),0,$I30*$J30) -> 0 | L30: =IF($K30=0,0,SUMIFS('Carga (PSE)'!$G$8:$G$1007,'Carga (PSE)'!$B$8:$B$1007,$G30)/MAX(1,COUNTIF(Cadastro!$T$7:$T$66,"Ativo"))/$K30) -> 0
B32: % Cumprido = carga média por atleta ativo realizada na semana (aba Carga (PSE)) ÷ carga prevista do microciclo. Verde = 90–110% do previsto; amarelo = acima; vermelho = abaixo.

Sheet Microciclo
A1: MICROCICLO — PLANEJAMENTO DA SEMANA
A2: Duas linhas por dia (duas sessões possíveis). As datas e os dias da semana são gerados a partir da Data de Início.
A4: IDENTIFICAÇÃO DO MICROCICLO
A5: Microciclo
A6: Semana nº no Macrociclo
A7: Data de Início (2ª feira) | B7: 46258
A8: Tipo de Microciclo
A9: Objetivo da Semana
A11: SESSÕES DA SEMANA
A12: Dia da Semana | B12: Data | C12: Turno | D12: Tipo de Sessão | E12: Local | F12: Duração (min) | G12: PSE Prevista | H12: Carga Prevista (UA) | I12: Ênfase Técnica | J12: Ênfase Tática | K12: Ênfase Física / Prevenção | L12: Observações
A13: =IF($B13="","",CHOOSE(WEEKDAY($B13,2),"Segunda-feira","Terça-feira","Quarta-feira","Quinta-feira","Sexta-feira","Sábado","Domingo")) -> Segunda-feira | B13: =IF($B$7="","",$B$7+INT((ROW()-13)/2)) -> 46258 | H13: =IF(OR($F13="",$G13=""),0,$F13*$G13) -> 0
A14: =IF($B14="","",CHOOSE(WEEKDAY($B14,2),"Segunda-feira","Terça-feira","Quarta-feira","Quinta-feira","Sexta-feira","Sábado","Domingo")) -> Segunda-feira | B14: =IF($B$7="","",$B$7+INT((ROW()-13)/2)) -> 46258 | H14: =IF(OR($F14="",$G14=""),0,$F14*$G14) -> 0
A15: =IF($B15="","",CHOOSE(WEEKDAY($B15,2),"Segunda-feira","Terça-feira","Quarta-feira","Quinta-feira","Sexta-feira","Sábado","Domingo")) -> Terça-feira | B15: =IF($B$7="","",$B$7+INT((ROW()-13)/2)) -> 46259 | H15: =IF(OR($F15="",$G15=""),0,$F15*$G15) -> 0
A16: =IF($B16="","",CHOOSE(WEEKDAY($B16,2),"Segunda-feira","Terça-feira","Quarta-feira","Quinta-feira","Sexta-feira","Sábado","Domingo")) -> Terça-feira | B16: =IF($B$7="","",$B$7+INT((ROW()-13)/2)) -> 46259 | H16: =IF(OR($F16="",$G16=""),0,$F16*$G16) -> 0
A17: =IF($B17="","",CHOOSE(WEEKDAY($B17,2),"Segunda-feira","Terça-feira","Quarta-feira","Quinta-feira","Sexta-feira","Sábado","Domingo")) -> Quarta-feira | B17: =IF($B$7="","",$B$7+INT((ROW()-13)/2)) -> 46260 | H17: =IF(OR($F17="",$G17=""),0,$F17*$G17) -> 0
A18: =IF($B18="","",CHOOSE(WEEKDAY($B18,2),"Segunda-feira","Terça-feira","Quarta-feira","Quinta-feira","Sexta-feira","Sábado","Domingo")) -> Quarta-feira | B18: =IF($B$7="","",$B$7+INT((ROW()-13)/2)) -> 46260 | H18: =IF(OR($F18="",$G18=""),0,$F18*$G18) -> 0
A19: =IF($B19="","",CHOOSE(WEEKDAY($B19,2),"Segunda-feira","Terça-feira","Quarta-feira","Quinta-feira","Sexta-feira","Sábado","Domingo")) -> Quinta-feira | B19: =IF($B$7="","",$B$7+INT((ROW()-13)/2)) -> 46261 | H19: =IF(OR($F19="",$G19=""),0,$F19*$G19) -> 0
A20: =IF($B20="","",CHOOSE(WEEKDAY($B20,2),"Segunda-feira","Terça-feira","Quarta-feira","Quinta-feira","Sexta-feira","Sábado","Domingo")) -> Quinta-feira | B20: =IF($B$7="","",$B$7+INT((ROW()-13)/2)) -> 46261 | H20: =IF(OR($F20="",$G20=""),0,$F20*$G20) -> 0
A21: =IF($B21="","",CHOOSE(WEEKDAY($B21,2),"Segunda-feira","Terça-feira","Quarta-feira","Quinta-feira","Sexta-feira","Sábado","Domingo")) -> Sexta-feira | B21: =IF($B$7="","",$B$7+INT((ROW()-13)/2)) -> 46262 | H21: =IF(OR($F21="",$G21=""),0,$F21*$G21) -> 0
A22: =IF($B22="","",CHOOSE(WEEKDAY($B22,2),"Segunda-feira","Terça-feira","Quarta-feira","Quinta-feira","Sexta-feira","Sábado","Domingo")) -> Sexta-feira | B22: =IF($B$7="","",$B$7+INT((ROW()-13)/2)) -> 46262 | H22: =IF(OR($F22="",$G22=""),0,$F22*$G22) -> 0
A23: =IF($B23="","",CHOOSE(WEEKDAY($B23,2),"Segunda-feira","Terça-feira","Quarta-feira","Quinta-feira","Sexta-feira","Sábado","Domingo")) -> Sábado | B23: =IF($B$7="","",$B$7+INT((ROW()-13)/2)) -> 46263 | H23: =IF(OR($F23="",$G23=""),0,$F23*$G23) -> 0
A24: =IF($B24="","",CHOOSE(WEEKDAY($B24,2),"Segunda-feira","Terça-feira","Quarta-feira","Quinta-feira","Sexta-feira","Sábado","Domingo")) -> Sábado | B24: =IF($B$7="","",$B$7+INT((ROW()-13)/2)) -> 46263 | H24: =IF(OR($F24="",$G24=""),0,$F24*$G24) -> 0
... A26: =IF($B26="","",CHOOSE(WEEKDAY($B26,2),"Segunda-feira","Terça-feira","Quarta-feira","Quinta-feira","Sexta-feira","Sábado","Domingo")) -> Domingo | B26: =IF($B$7="","",$B$7+INT((ROW()-13)/2)) -> 46264 | H26: =IF(OR($F26="",$G26=""),0,$F26*$G26) -> 0
A27: TOTAL DA SEMANA | F27: =SUM(F13:F26) -> 0 | G27: =IFERROR(AVERAGE(G13:G26),"") | H27: =SUM(H13:H26) -> 0
A29: RESUMO DA SEMANA — PREVISTO × REALIZADO
A30: SESSÕES PLANEJADAS | C30: DURAÇÃO TOTAL (min) | E30: CARGA PREVISTA (UA) | G30: CARGA REALIZADA — MÉDIA/ATLETA (UA) | J30: % DE CUMPRIMENTO DA CARGA
A31: =COUNTA(D13:D26) -> 0 | C31: =SUM(F13:F26) -> 0 | E31: =SUM(H13:H26) -> 0 | G31: =IFERROR(SUMIFS('Carga (PSE)'!$G$8:$G$1007,'Carga (PSE)'!$B$8:$B$1007,$B$6)/MAX(1,COUNTIF(Cadastro!$T$7:$T$66,"Ativo")),0) -> 0 | J31: =IFERROR(G31/H27,0) -> 0
A34: DISTRIBUIÇÃO DE CONTEÚDOS POR DIA (minutos)
A35: Dia | B35: Técnico | C35: Tático | D35: Físico | E35: Preventivo / Prevenção | F35: Recuperação | G35: Total (min) | H35: % da Semana
A36: =IF($A13="","",$A13) -> Segunda-feira | G36: =SUM(B36:F36) -> 0 | H36: =IFERROR($G36/$G$43,0) -> 0
A37: =IF($A15="","",$A15) -> Terça-feira | G37: =SUM(B37:F37) -> 0 | H37: =IFERROR($G37/$G$43,0) -> 0
A38: =IF($A17="","",$A17) -> Quarta-feira | G38: =SUM(B38:F38) -> 0 | H38: =IFERROR($G38/$G$43,0) -> 0
A39: =IF($A19="","",$A19) -> Quinta-feira | G39: =SUM(B39:F39) -> 0 | H39: =IFERROR($G39/$G$43,0) -> 0
A40: =IF($A21="","",$A21) -> Sexta-feira | G40: =SUM(B40:F40) -> 0 | H40: =IFERROR($G40/$G$43,0) -> 0
A41: =IF($A23="","",$A23) -> Sábado | G41: =SUM(B41:F41) -> 0 | H41: =IFERROR($G41/$G$43,0) -> 0
A42: =IF($A25="","",$A25) -> Domingo | G42: =SUM(B42:F42) -> 0 | H42: =IFERROR($G42/$G$43,0) -> 0
A43: TOTAL | B43: =SUM(B36:B42) -> 0 | C43: =SUM(C36:C42) -> 0 | D43: =SUM(D36:D42) -> 0 | E43: =SUM(E36:E42) -> 0 | F43: =SUM(F36:F42) -> 0 | G43: =SUM(G36:G42) -> 0 | H43: =IFERROR(SUM(H36:H42),0) -> 0

Sheet Prescrição
A1: PRESCRIÇÃO DO TREINO
A2: Uma linha por exercício prescrito. Escolha o exercício no menu (vem da aba Exercícios) e defina o destinatário: 'Equipe (todos)' ou o nome de um atleta — é assim que o treino chega à Área do Atleta.
A3: RESUMO DA SESSÃO SELECIONADA
A4: Data: | B4: 46265 | E4: EXERCÍCIOS PRESCRITOS | G4: DURAÇÃO TOTAL (min) | I4: CARGA PREVISTA (UA) | K4: PSE MÉDIA PREVISTA | M4: MIN. TÉCNICO | O4: MIN. TÁTICO | Q4: MIN. FÍSICO | S4: MIN. PREVENTIVO
E5: =COUNTIFS($A$8:$A$507,$B$4) -> 0 | G5: =SUMIFS($O$8:$O$507,$A$8:$A$507,$B$4) -> 0 | I5: =SUMIFS($R$8:$R$507,$A$8:$A$507,$B$4) -> 0 | K5: =IFERROR(AVERAGEIFS($P$8:$P$507,$A$8:$A$507,$B$4),0) -> 0 | M5: =SUMIFS($O$8:$O$507,$A$8:$A$507,$B$4,$H$8:$H$507,"Técnico") -> 0 | O5: =SUMIFS($O$8:$O$507,$A$8:$A$507,$B$4,$H$8:$H$507,"Tático") -> 0 | Q5: =SUMIFS($O$8:$O$507,$A$8:$A$507,$B$4,$H$8:$H$507,"Físico") -> 0 | S5: =SUMIFS($O$8:$O$507,$A$8:$A$507,$B$4,$H$8:$H$507,"Preventivo/Compensatório") -> 0
A6: Digite a data em B4 para ver o resumo das sessões daquele dia. Séries × Repetições geram o Volume; Duração × PSE Prevista geram a Carga Prevista em UA (unidades arbitrárias).
A7: Data | B7: Semana | C7: Sessão | D7: Turno | E7: Destinatário | F7: Bloco | G7: Exercício | H7: Categoria | I7: Fundamento | J7: Capacidade Física | K7: Séries | L7: Repetições / Tempo | M7: Carga / Intensidade | N7: Pausa (s) | O7: Duração (min) | P7: PSE Prev. | Q7: Volume | R7: Carga Prev. (UA) | S7: Progressão / Critério | T7: Observações | U7: Índ.
B8: =IF($A8="",0,INT(($A8-Macrociclo!$C$11)/7)+1) -> 0 | H8: =IFERROR(INDEX(Exercícios!$C$7:$C$206,MATCH($G8,Exercícios!$B$7:$B$206,0)),"") | I8: =IFERROR(INDEX(Exercícios!$D$7:$D$206,MATCH($G8,Exercícios!$B$7:$B$206,0)),"") | J8: =IFERROR(INDEX(Exercícios!$E$7:$E$206,MATCH($G8,Exercícios!$B$7:$B$206,0)),"") | Q8: =IFERROR($K8*$L8,"") -> 0 | R8: =IF(OR($O8="",$P8=""),0,$O8*$P8) -> 0 | U8: =IF($A8="",0,IF(AND(OR($E8=Atleta!$C$4,$E8="Equipe (todos)"),$A8>=Atleta!$C$5),MAX($U$7:U7)+1,0)) -> 0
B9: =IF($A9="",0,INT(($A9-Macrociclo!$C$11)/7)+1) -> 0 | H9: =IFERROR(INDEX(Exercícios!$C$7:$C$206,MATCH($G9,Exercícios!$B$7:$B$206,0)),"") | I9: =IFERROR(INDEX(Exercícios!$D$7:$D$206,MATCH($G9,Exercícios!$B$7:$B$206,0)),"") | J9: =IFERROR(INDEX(Exercícios!$E$7:$E$206,MATCH($G9,Exercícios!$B$7:$B$206,0)),"") | Q9: =IFERROR($K9*$L9,"") -> 0 | R9: =IF(OR($O9="",$P9=""),0,$O9*$P9) -> 0 | U9: =IF($A9="",0,IF(AND(OR($E9=Atleta!$C$4,$E9="Equipe (todos)"),$A9>=Atleta!$C$5),MAX($U$7:U8)+1,0)) -> 0
B10: =IF($A10="",0,INT(($A10-Macrociclo!$C$11)/7)+1) -> 0 | H10: =IFERROR(INDEX(Exercícios!$C$7:$C$206,MATCH($G10,Exercícios!$B$7:$B$206,0)),"") | I10: =IFERROR(INDEX(Exercícios!$D$7:$D$206,MATCH($G10,Exercícios!$B$7:$B$206,0)),"") | J10: =IFERROR(INDEX(Exercícios!$E$7:$E$206,MATCH($G10,Exercícios!$B$7:$B$206,0)),"") | Q10: =IFERROR($K10*$L10,"") -> 0 | R10: =IF(OR($O10="",$P10=""),0,$O10*$P10) -> 0 | U10: =IF($A10="",0,IF(AND(OR($E10=Atleta!$C$4,$E10="Equipe (todos)"),$A10>=Atleta!$C$5),MAX($U$7:U9)+1,0)) -> 0
B11: =IF($A11="",0,INT(($A11-Macrociclo!$C$11)/7)+1) -> 0 | H11: =IFERROR(INDEX(Exercícios!$C$7:$C$206,MATCH($G11,Exercícios!$B$7:$B$206,0)),"") | I11: =IFERROR(INDEX(Exercícios!$D$7:$D$206,MATCH($G11,Exercícios!$B$7:$B$206,0)),"") | J11: =IFERROR(INDEX(Exercícios!$E$7:$E$206,MATCH($G11,Exercícios!$B$7:$B$206,0)),"") | Q11: =IFERROR($K11*$L11,"") -> 0 | R11: =IF(OR($O11="",$P11=""),0,$O11*$P11) -> 0 | U11: =IF($A11="",0,IF(AND(OR($E11=Atleta!$C$4,$E11="Equipe (todos)"),$A11>=Atleta!$C$5),MAX($U$7:U10)+1,0)) -> 0
B12: =IF($A12="",0,INT(($A12-Macrociclo!$C$11)/7)+1) -> 0 | H12: =IFERROR(INDEX(Exercícios!$C$7:$C$206,MATCH($G12,Exercícios!$B$7:$B$206,0)),"") | I12: =IFERROR(INDEX(Exercícios!$D$7:$D$206,MATCH($G12,Exercícios!$B$7:$B$206,0)),"") | J12: =IFERROR(INDEX(Exercícios!$E$7:$E$206,MATCH($G12,Exercícios!$B$7:$B$206,0)),"") | Q12: =IFERROR($K12*$L12,"") -> 0 | R12: =IF(OR($O12="",$P12=""),0,$O12*$P12) -> 0 | U12: =IF($A12="",0,IF(AND(OR($E12=Atleta!$C$4,$E12="Equipe (todos)"),$A12>=Atleta!$C$5),MAX($U$7:U11)+1,0)) -> 0
B13: =IF($A13="",0,INT(($A13-Macrociclo!$C$11)/7)+1) -> 0 | H13: =IFERROR(INDEX(Exercícios!$C$7:$C$206,MATCH($G13,Exercícios!$B$7:$B$206,0)),"") | I13: =IFERROR(INDEX(Exercícios!$D$7:$D$206,MATCH($G13,Exercícios!$B$7:$B$206,0)),"") | J13: =IFERROR(INDEX(Exercícios!$E$7:$E$206,MATCH($G13,Exercícios!$B$7:$B$206,0)),"") | Q13: =IFERROR($K13*$L13,"") -> 0 | R13: =IF(OR($O13="",$P13=""),0,$O13*$P13) -> 0 | U13: =IF($A13="",0,IF(AND(OR($E13=Atleta!$C$4,$E13="Equipe (todos)"),$A13>=Atleta!$C$5),MAX($U$7:U12)+1,0)) -> 0
B14: =IF($A14="",0,INT(($A14-Macrociclo!$C$11)/7)+1) -> 0 | H14: =IFERROR(INDEX(Exercícios!$C$7:$C$206,MATCH($G14,Exercícios!$B$7:$B$206,0)),"") | I14: =IFERROR(INDEX(Exercícios!$D$7:$D$206,MATCH($G14,Exercícios!$B$7:$B$206,0)),"") | J14: =IFERROR(INDEX(Exercícios!$E$7:$E$206,MATCH($G14,Exercícios!$B$7:$B$206,0)),"") | Q14: =IFERROR($K14*$L14,"") -> 0 | R14: =IF(OR($O14="",$P14=""),0,$O14*$P14) -> 0 | U14: =IF($A14="",0,IF(AND(OR($E14=Atleta!$C$4,$E14="Equipe (todos)"),$A14>=Atleta!$C$5),MAX($U$7:U13)+1,0)) -> 0
B15: =IF($A15="",0,INT(($A15-Macrociclo!$C$11)/7)+1) -> 0 | H15: =IFERROR(INDEX(Exercícios!$C$7:$C$206,MATCH($G15,Exercícios!$B$7:$B$206,0)),"") | I15: =IFERROR(INDEX(Exercícios!$D$7:$D$206,MATCH($G15,Exercícios!$B$7:$B$206,0)),"") | J15: =IFERROR(INDEX(Exercícios!$E$7:$E$206,MATCH($G15,Exercícios!$B$7:$B$206,0)),"") | Q15: =IFERROR($K15*$L15,"") -> 0 | R15: =IF(OR($O15="",$P15=""),0,$O15*$P15) -> 0 | U15: =IF($A15="",0,IF(AND(OR($E15=Atleta!$C$4,$E15="Equipe (todos)"),$A15>=Atleta!$C$5),MAX($U$7:U14)+1,0)) -> 0
B16: =IF($A16="",0,INT(($A16-Macrociclo!$C$11)/7)+1) -> 0 | H16: =IFERROR(INDEX(Exercícios!$C$7:$C$206,MATCH($G16,Exercícios!$B$7:$B$206,0)),"") | I16: =IFERROR(INDEX(Exercícios!$D$7:$D$206,MATCH($G16,Exercícios!$B$7:$B$206,0)),"") | J16: =IFERROR(INDEX(Exercícios!$E$7:$E$206,MATCH($G16,Exercícios!$B$7:$B$206,0)),"") | Q16: =IFERROR($K16*$L16,"") -> 0 | R16: =IF(OR($O16="",$P16=""),0,$O16*$P16) -> 0 | U16: =IF($A16="",0,IF(AND(OR($E16=Atleta!$C$4,$E16="Equipe (todos)"),$A16>=Atleta!$C$5),MAX($U$7:U15)+1,0)) -> 0
B17: =IF($A17="",0,INT(($A17-Macrociclo!$C$11)/7)+1) -> 0 | H17: =IFERROR(INDEX(Exercícios!$C$7:$C$206,MATCH($G17,Exercícios!$B$7:$B$206,0)),"") | I17: =IFERROR(INDEX(Exercícios!$D$7:$D$206,MATCH($G17,Exercícios!$B$7:$B$206,0)),"") | J17: =IFERROR(INDEX(Exercícios!$E$7:$E$206,MATCH($G17,Exercícios!$B$7:$B$206,0)),"") | Q17: =IFERROR($K17*$L17,"") -> 0 | R17: =IF(OR($O17="",$P17=""),0,$O17*$P17) -> 0 | U17: =IF($A17="",0,IF(AND(OR($E17=Atleta!$C$4,$E17="Equipe (todos)"),$A17>=Atleta!$C$5),MAX($U$7:U16)+1,0)) -> 0
B18: =IF($A18="",0,INT(($A18-Macrociclo!$C$11)/7)+1) -> 0 | H18: =IFERROR(INDEX(Exercícios!$C$7:$C$206,MATCH($G18,Exercícios!$B$7:$B$206,0)),"") | I18: =IFERROR(INDEX(Exercícios!$D$7:$D$206,MATCH($G18,Exercícios!$B$7:$B$206,0)),"") | J18: =IFERROR(INDEX(Exercícios!$E$7:$E$206,MATCH($G18,Exercícios!$B$7:$B$206,0)),"") | Q18: =IFERROR($K18*$L18,"") -> 0 | R18: =IF(OR($O18="",$P18=""),0,$O18*$P18) -> 0 | U18: =IF($A18="",0,IF(AND(OR($E18=Atleta!$C$4,$E18="Equipe (todos)"),$A18>=Atleta!$C$5),MAX($U$7:U17)+1,0)) -> 0
B19: =IF($A19="",0,INT(($A19-Macrociclo!$C$11)/7)+1) -> 0 | H19: =IFERROR(INDEX(Exercícios!$C$7:$C$206,MATCH($G19,Exercícios!$B$7:$B$206,0)),"") | I19: =IFERROR(INDEX(Exercícios!$D$7:$D$206,MATCH($G19,Exercícios!$B$7:$B$206,0)),"") | J19: =IFERROR(INDEX(Exercícios!$E$7:$E$206,MATCH($G19,Exercícios!$B$7:$B$206,0)),"") | Q19: =IFERROR($K19*$L19,"") -> 0 | R19: =IF(OR($O19="",$P19=""),0,$O19*$P19) -> 0 | U19: =IF($A19="",0,IF(AND(OR($E19=Atleta!$C$4,$E19="Equipe (todos)"),$A19>=Atleta!$C$5),MAX($U$7:U18)+1,0)) -> 0
... B507: =IF($A507="",0,INT(($A507-Macrociclo!$C$11)/7)+1) -> 0 | H507: =IFERROR(INDEX(Exercícios!$C$7:$C$206,MATCH($G507,Exercícios!$B$7:$B$206,0)),"") | I507: =IFERROR(INDEX(Exercícios!$D$7:$D$206,MATCH($G507,Exercícios!$B$7:$B$206,0)),"") | J507: =IFERROR(INDEX(Exercícios!$E$7:$E$206,MATCH($G507,Exercícios!$B$7:$B$206,0)),"") | Q507: =IFERROR($K507*$L507,"") -> 0 | R507: =IF(OR($O507="",$P507=""),0,$O507*$P507) -> 0 | U507: =IF($A507="",0,IF(AND(OR($E507=Atleta!$C$4,$E507="Equipe (todos)"),$A507>=Atleta!$C$5),MAX($U$7:U506)+1,0)) -> 0

Sheet Carga (PSE)
A1: CONTROLE DE CARGA INTERNA — MÉTODO DA PSE DA SESSÃO
A2: Registre duração e PSE (0–10, coletada ~30 min após o treino). Carga, aguda, crônica, ACWR e zona de risco são automáticos.
A4: Carga (UA) = Duração × PSE • ACWR = Carga Aguda (7 d) ÷ Carga Crônica (média semanal dos 28 d). Faixas: < 0,80 subcarga | 0,80–1,30 zona ideal | 1,31–1,50 atenção | > 1,50 risco elevado. A Zona só é classificada após 21 dias de registros do atleta — antes disso aparece 'Histórico insuficiente'.
A7: Data | B7: Semana | C7: Atleta | D7: Tipo de Sessão | E7: Duração (min) | F7: PSE (0-10) | G7: Carga (UA) | H7: Carga Aguda 7 d | I7: Carga Crônica 28 d | J7: ACWR | K7: Dias de Histórico | L7: Zona / Alerta | M7: Observações
B8: =IF($A8="",0,INT(($A8-Macrociclo!$C$11)/7)+1) -> 0 | G8: =IF(OR($E8="",$F8=""),0,$E8*$F8) -> 0 | H8: =IF($A8="",0,SUMIFS($G$8:$G$1007,$C$8:$C$1007,$C8,$A$8:$A$1007,">="&$A8-6,$A$8:$A$1007,"<="&$A8)) -> 0 | I8: =IF($A8="",0,SUMIFS($G$8:$G$1007,$C$8:$C$1007,$C8,$A$8:$A$1007,">="&$A8-27,$A$8:$A$1007,"<="&$A8)/4) -> 0 | J8: =IF(OR($A8="",$I8=0),0,$H8/$I8) -> 0 | K8: =IF($A8="",0,$A8-SUMPRODUCT(MIN(($C$8:$C$1007=$C8)*$A$8:$A$1007+($C$8:$C$1007<>$C8)*100000))+1) -> 0 | L8: =IF($A8="","",IF($J8=0,"Sem registro anterior",IF($K8<21,"Histórico insuficiente",IF($J8<0.8,"Subcarga",IF($J8<=1.3,"Zona ideal",IF($J8<=1.5,"Atenção","Risco elevado"))))))
B9: =IF($A9="",0,INT(($A9-Macrociclo!$C$11)/7)+1) -> 0 | G9: =IF(OR($E9="",$F9=""),0,$E9*$F9) -> 0 | H9: =IF($A9="",0,SUMIFS($G$8:$G$1007,$C$8:$C$1007,$C9,$A$8:$A$1007,">="&$A9-6,$A$8:$A$1007,"<="&$A9)) -> 0 | I9: =IF($A9="",0,SUMIFS($G$8:$G$1007,$C$8:$C$1007,$C9,$A$8:$A$1007,">="&$A9-27,$A$8:$A$1007,"<="&$A9)/4) -> 0 | J9: =IF(OR($A9="",$I9=0),0,$H9/$I9) -> 0 | K9: =IF($A9="",0,$A9-SUMPRODUCT(MIN(($C$8:$C$1007=$C9)*$A$8:$A$1007+($C$8:$C$1007<>$C9)*100000))+1) -> 0 | L9: =IF($A9="","",IF($J9=0,"Sem registro anterior",IF($K9<21,"Histórico insuficiente",IF($J9<0.8,"Subcarga",IF($J9<=1.3,"Zona ideal",IF($J9<=1.5,"Atenção","Risco elevado"))))))
B10: =IF($A10="",0,INT(($A10-Macrociclo!$C$11)/7)+1) -> 0 | G10: =IF(OR($E10="",$F10=""),0,$E10*$F10) -> 0 | H10: =IF($A10="",0,SUMIFS($G$8:$G$1007,$C$8:$C$1007,$C10,$A$8:$A$1007,">="&$A10-6,$A$8:$A$1007,"<="&$A10)) -> 0 | I10: =IF($A10="",0,SUMIFS($G$8:$G$1007,$C$8:$C$1007,$C10,$A$8:$A$1007,">="&$A10-27,$A$8:$A$1007,"<="&$A10)/4) -> 0 | J10: =IF(OR($A10="",$I10=0),0,$H10/$I10) -> 0 | K10: =IF($A10="",0,$A10-SUMPRODUCT(MIN(($C$8:$C$1007=$C10)*$A$8:$A$1007+($C$8:$C$1007<>$C10)*100000))+1) -> 0 | L10: =IF($A10="","",IF($J10=0,"Sem registro anterior",IF($K10<21,"Histórico insuficiente",IF($J10<0.8,"Subcarga",IF($J10<=1.3,"Zona ideal",IF($J10<=1.5,"Atenção","Risco elevado"))))))
B11: =IF($A11="",0,INT(($A11-Macrociclo!$C$11)/7)+1) -> 0 | G11: =IF(OR($E11="",$F11=""),0,$E11*$F11) -> 0 | H11: =IF($A11="",0,SUMIFS($G$8:$G$1007,$C$8:$C$1007,$C11,$A$8:$A$1007,">="&$A11-6,$A$8:$A$1007,"<="&$A11)) -> 0 | I11: =IF($A11="",0,SUMIFS($G$8:$G$1007,$C$8:$C$1007,$C11,$A$8:$A$1007,">="&$A11-27,$A$8:$A$1007,"<="&$A11)/4) -> 0 | J11: =IF(OR($A11="",$I11=0),0,$H11/$I11) -> 0 | K11: =IF($A11="",0,$A11-SUMPRODUCT(MIN(($C$8:$C$1007=$C11)*$A$8:$A$1007+($C$8:$C$1007<>$C11)*100000))+1) -> 0 | L11: =IF($A11="","",IF($J11=0,"Sem registro anterior",IF($K11<21,"Histórico insuficiente",IF($J11<0.8,"Subcarga",IF($J11<=1.3,"Zona ideal",IF($J11<=1.5,"Atenção","Risco elevado"))))))
B12: =IF($A12="",0,INT(($A12-Macrociclo!$C$11)/7)+1) -> 0 | G12: =IF(OR($E12="",$F12=""),0,$E12*$F12) -> 0 | H12: =IF($A12="",0,SUMIFS($G$8:$G$1007,$C$8:$C$1007,$C12,$A$8:$A$1007,">="&$A12-6,$A$8:$A$1007,"<="&$A12)) -> 0 | I12: =IF($A12="",0,SUMIFS($G$8:$G$1007,$C$8:$C$1007,$C12,$A$8:$A$1007,">="&$A12-27,$A$8:$A$1007,"<="&$A12)/4) -> 0 | J12: =IF(OR($A12="",$I12=0),0,$H12/$I12) -> 0 | K12: =IF($A12="",0,$A12-SUMPRODUCT(MIN(($C$8:$C$1007=$C12)*$A$8:$A$1007+($C$8:$C$1007<>$C12)*100000))+1) -> 0 | L12: =IF($A12="","",IF($J12=0,"Sem registro anterior",IF($K12<21,"Histórico insuficiente",IF($J12<0.8,"Subcarga",IF($J12<=1.3,"Zona ideal",IF($J12<=1.5,"Atenção","Risco elevado"))))))
B13: =IF($A13="",0,INT(($A13-Macrociclo!$C$11)/7)+1) -> 0 | G13: =IF(OR($E13="",$F13=""),0,$E13*$F13) -> 0 | H13: =IF($A13="",0,SUMIFS($G$8:$G$1007,$C$8:$C$1007,$C13,$A$8:$A$1007,">="&$A13-6,$A$8:$A$1007,"<="&$A13)) -> 0 | I13: =IF($A13="",0,SUMIFS($G$8:$G$1007,$C$8:$C$1007,$C13,$A$8:$A$1007,">="&$A13-27,$A$8:$A$1007,"<="&$A13)/4) -> 0 | J13: =IF(OR($A13="",$I13=0),0,$H13/$I13) -> 0 | K13: =IF($A13="",0,$A13-SUMPRODUCT(MIN(($C$8:$C$1007=$C13)*$A$8:$A$1007+($C$8:$C$1007<>$C13)*100000))+1) -> 0 | L13: =IF($A13="","",IF($J13=0,"Sem registro anterior",IF($K13<21,"Histórico insuficiente",IF($J13<0.8,"Subcarga",IF($J13<=1.3,"Zona ideal",IF($J13<=1.5,"Atenção","Risco elevado"))))))
B14: =IF($A14="",0,INT(($A14-Macrociclo!$C$11)/7)+1) -> 0 | G14: =IF(OR($E14="",$F14=""),0,$E14*$F14) -> 0 | H14: =IF($A14="",0,SUMIFS($G$8:$G$1007,$C$8:$C$1007,$C14,$A$8:$A$1007,">="&$A14-6,$A$8:$A$1007,"<="&$A14)) -> 0 | I14: =IF($A14="",0,SUMIFS($G$8:$G$1007,$C$8:$C$1007,$C14,$A$8:$A$1007,">="&$A14-27,$A$8:$A$1007,"<="&$A14)/4) -> 0 | J14: =IF(OR($A14="",$I14=0),0,$H14/$I14) -> 0 | K14: =IF($A14="",0,$A14-SUMPRODUCT(MIN(($C$8:$C$1007=$C14)*$A$8:$A$1007+($C$8:$C$1007<>$C14)*100000))+1) -> 0 | L14: =IF($A14="","",IF($J14=0,"Sem registro anterior",IF($K14<21,"Histórico insuficiente",IF($J14<0.8,"Subcarga",IF($J14<=1.3,"Zona ideal",IF($J14<=1.5,"Atenção","Risco elevado"))))))
B15: =IF($A15="",0,INT(($A15-Macrociclo!$C$11)/7)+1) -> 0 | G15: =IF(OR($E15="",$F15=""),0,$E15*$F15) -> 0 | H15: =IF($A15="",0,SUMIFS($G$8:$G$1007,$C$8:$C$1007,$C15,$A$8:$A$1007,">="&$A15-6,$A$8:$A$1007,"<="&$A15)) -> 0 | I15: =IF($A15="",0,SUMIFS($G$8:$G$1007,$C$8:$C$1007,$C15,$A$8:$A$1007,">="&$A15-27,$A$8:$A$1007,"<="&$A15)/4) -> 0 | J15: =IF(OR($A15="",$I15=0),0,$H15/$I15) -> 0 | K15: =IF($A15="",0,$A15-SUMPRODUCT(MIN(($C$8:$C$1007=$C15)*$A$8:$A$1007+($C$8:$C$1007<>$C15)*100000))+1) -> 0 | L15: =IF($A15="","",IF($J15=0,"Sem registro anterior",IF($K15<21,"Histórico insuficiente",IF($J15<0.8,"Subcarga",IF($J15<=1.3,"Zona ideal",IF($J15<=1.5,"Atenção","Risco elevado"))))))
B16: =IF($A16="",0,INT(($A16-Macrociclo!$C$11)/7)+1) -> 0 | G16: =IF(OR($E16="",$F16=""),0,$E16*$F16) -> 0 | H16: =IF($A16="",0,SUMIFS($G$8:$G$1007,$C$8:$C$1007,$C16,$A$8:$A$1007,">="&$A16-6,$A$8:$A$1007,"<="&$A16)) -> 0 | I16: =IF($A16="",0,SUMIFS($G$8:$G$1007,$C$8:$C$1007,$C16,$A$8:$A$1007,">="&$A16-27,$A$8:$A$1007,"<="&$A16)/4) -> 0 | J16: =IF(OR($A16="",$I16=0),0,$H16/$I16) -> 0 | K16: =IF($A16="",0,$A16-SUMPRODUCT(MIN(($C$8:$C$1007=$C16)*$A$8:$A$1007+($C$8:$C$1007<>$C16)*100000))+1) -> 0 | L16: =IF($A16="","",IF($J16=0,"Sem registro anterior",IF($K16<21,"Histórico insuficiente",IF($J16<0.8,"Subcarga",IF($J16<=1.3,"Zona ideal",IF($J16<=1.5,"Atenção","Risco elevado"))))))
B17: =IF($A17="",0,INT(($A17-Macrociclo!$C$11)/7)+1) -> 0 | G17: =IF(OR($E17="",$F17=""),0,$E17*$F17) -> 0 | H17: =IF($A17="",0,SUMIFS($G$8:$G$1007,$C$8:$C$1007,$C17,$A$8:$A$1007,">="&$A17-6,$A$8:$A$1007,"<="&$A17)) -> 0 | I17: =IF($A17="",0,SUMIFS($G$8:$G$1007,$C$8:$C$1007,$C17,$A$8:$A$1007,">="&$A17-27,$A$8:$A$1007,"<="&$A17)/4) -> 0 | J17: =IF(OR($A17="",$I17=0),0,$H17/$I17) -> 0 | K17: =IF($A17="",0,$A17-SUMPRODUCT(MIN(($C$8:$C$1007=$C17)*$A$8:$A$1007+($C$8:$C$1007<>$C17)*100000))+1) -> 0 | L17: =IF($A17="","",IF($J17=0,"Sem registro anterior",IF($K17<21,"Histórico insuficiente",IF($J17<0.8,"Subcarga",IF($J17<=1.3,"Zona ideal",IF($J17<=1.5,"Atenção","Risco elevado"))))))
B18: =IF($A18="",0,INT(($A18-Macrociclo!$C$11)/7)+1) -> 0 | G18: =IF(OR($E18="",$F18=""),0,$E18*$F18) -> 0 | H18: =IF($A18="",0,SUMIFS($G$8:$G$1007,$C$8:$C$1007,$C18,$A$8:$A$1007,">="&$A18-6,$A$8:$A$1007,"<="&$A18)) -> 0 | I18: =IF($A18="",0,SUMIFS($G$8:$G$1007,$C$8:$C$1007,$C18,$A$8:$A$1007,">="&$A18-27,$A$8:$A$1007,"<="&$A18)/4) -> 0 | J18: =IF(OR($A18="",$I18=0),0,$H18/$I18) -> 0 | K18: =IF($A18="",0,$A18-SUMPRODUCT(MIN(($C$8:$C$1007=$C18)*$A$8:$A$1007+($C$8:$C$1007<>$C18)*100000))+1) -> 0 | L18: =IF($A18="","",IF($J18=0,"Sem registro anterior",IF($K18<21,"Histórico insuficiente",IF($J18<0.8,"Subcarga",IF($J18<=1.3,"Zona ideal",IF($J18<=1.5,"Atenção","Risco elevado"))))))
B19: =IF($A19="",0,INT(($A19-Macrociclo!$C$11)/7)+1) -> 0 | G19: =IF(OR($E19="",$F19=""),0,$E19*$F19) -> 0 | H19: =IF($A19="",0,SUMIFS($G$8:$G$1007,$C$8:$C$1007,$C19,$A$8:$A$1007,">="&$A19-6,$A$8:$A$1007,"<="&$A19)) -> 0 | I19: =IF($A19="",0,SUMIFS($G$8:$G$1007,$C$8:$C$1007,$C19,$A$8:$A$1007,">="&$A19-27,$A$8:$A$1007,"<="&$A19)/4) -> 0 | J19: =IF(OR($A19="",$I19=0),0,$H19/$I19) -> 0 | K19: =IF($A19="",0,$A19-SUMPRODUCT(MIN(($C$8:$C$1007=$C19)*$A$8:$A$1007+($C$8:$C$1007<>$C19)*100000))+1) -> 0 | L19: =IF($A19="","",IF($J19=0,"Sem registro anterior",IF($K19<21,"Histórico insuficiente",IF($J19<0.8,"Subcarga",IF($J19<=1.3,"Zona ideal",IF($J19<=1.5,"Atenção","Risco elevado"))))))
... B1007: =IF($A1007="",0,INT(($A1007-Macrociclo!$C$11)/7)+1) -> 0 | G1007: =IF(OR($E1007="",$F1007=""),0,$E1007*$F1007) -> 0 | H1007: =IF($A1007="",0,SUMIFS($G$8:$G$1007,$C$8:$C$1007,$C1007,$A$8:$A$1007,">="&$A1007-6,$A$8:$A$1007,"<="&$A1007)) -> 0 | I1007: =IF($A1007="",0,SUMIFS($G$8:$G$1007,$C$8:$C$1007,$C1007,$A$8:$A$1007,">="&$A1007-27,$A$8:$A$1007,"<="&$A1007)/4) -> 0 | J1007: =IF(OR($A1007="",$I1007=0),0,$H1007/$I1007) -> 0 | K1007: =IF($A1007="",0,$A1007-SUMPRODUCT(MIN(($C$8:$C$1007=$C1007)*$A$8:$A$1007+($C$8:$C$1007<>$C1007)*100000))+1) -> 0 | L1007: =IF($A1007="","",IF($J1007=0,"Sem registro anterior",IF($K1007<21,"Histórico insuficiente",IF($J1007<0.8,"Subcarga",IF($J1007<=1.3,"Zona ideal",IF($J1007<=1.5,"Atenção","Risco elevado"))))))

Sheet Wellness
A1: WELLNESS DIÁRIO — ÍNDICE DE HOOPER
A2: Cada item de 1 (muito bom / ausente) a 7 (muito ruim / máxima). Soma de 4 a 28 — QUANTO MAIOR, PIOR. Aplicar antes do treino.
A4: Classificação: 4–8 Ótimo | 9–12 Bom | 13–16 Regular | 17–20 Alerta | 21–28 Crítico. Referência: Hooper & Mackinnon (1995). Pontuações em Alerta/Crítico por 2 dias seguidos pedem conversa com o atleta e eventual ajuste da carga do dia.
A7: Data | B7: Semana | C7: Atleta | D7: Qualidade do Sono (1-7) | E7: Estresse (1-7) | F7: Fadiga (1-7) | G7: Dor Muscular (1-7) | H7: Índice de Hooper | I7: Classificação | J7: Local da Dor / Queixa | K7: Observações
B8: =IF($A8="",0,INT(($A8-Macrociclo!$C$11)/7)+1) -> 0 | H8: =IF(COUNT($D8:$G8)<4,0,SUM($D8:$G8)) -> 0 | I8: =IF($H8=0,"",IF($H8<=8,"Ótimo",IF($H8<=12,"Bom",IF($H8<=16,"Regular",IF($H8<=20,"Alerta","Crítico")))))
B9: =IF($A9="",0,INT(($A9-Macrociclo!$C$11)/7)+1) -> 0 | H9: =IF(COUNT($D9:$G9)<4,0,SUM($D9:$G9)) -> 0 | I9: =IF($H9=0,"",IF($H9<=8,"Ótimo",IF($H9<=12,"Bom",IF($H9<=16,"Regular",IF($H9<=20,"Alerta","Crítico")))))
B10: =IF($A10="",0,INT(($A10-Macrociclo!$C$11)/7)+1) -> 0 | H10: =IF(COUNT($D10:$G10)<4,0,SUM($D10:$G10)) -> 0 | I10: =IF($H10=0,"",IF($H10<=8,"Ótimo",IF($H10<=12,"Bom",IF($H10<=16,"Regular",IF($H10<=20,"Alerta","Crítico")))))
B11: =IF($A11="",0,INT(($A11-Macrociclo!$C$11)/7)+1) -> 0 | H11: =IF(COUNT($D11:$G11)<4,0,SUM($D11:$G11)) -> 0 | I11: =IF($H11=0,"",IF($H11<=8,"Ótimo",IF($H11<=12,"Bom",IF($H11<=16,"Regular",IF($H11<=20,"Alerta","Crítico")))))
B12: =IF($A12="",0,INT(($A12-Macrociclo!$C$11)/7)+1) -> 0 | H12: =IF(COUNT($D12:$G12)<4,0,SUM($D12:$G12)) -> 0 | I12: =IF($H12=0,"",IF($H12<=8,"Ótimo",IF($H12<=12,"Bom",IF($H12<=16,"Regular",IF($H12<=20,"Alerta","Crítico")))))
B13: =IF($A13="",0,INT(($A13-Macrociclo!$C$11)/7)+1) -> 0 | H13: =IF(COUNT($D13:$G13)<4,0,SUM($D13:$G13)) -> 0 | I13: =IF($H13=0,"",IF($H13<=8,"Ótimo",IF($H13<=12,"Bom",IF($H13<=16,"Regular",IF($H13<=20,"Alerta","Crítico")))))
B14: =IF($A14="",0,INT(($A14-Macrociclo!$C$11)/7)+1) -> 0 | H14: =IF(COUNT($D14:$G14)<4,0,SUM($D14:$G14)) -> 0 | I14: =IF($H14=0,"",IF($H14<=8,"Ótimo",IF($H14<=12,"Bom",IF($H14<=16,"Regular",IF($H14<=20,"Alerta","Crítico")))))
B15: =IF($A15="",0,INT(($A15-Macrociclo!$C$11)/7)+1) -> 0 | H15: =IF(COUNT($D15:$G15)<4,0,SUM($D15:$G15)) -> 0 | I15: =IF($H15=0,"",IF($H15<=8,"Ótimo",IF($H15<=12,"Bom",IF($H15<=16,"Regular",IF($H15<=20,"Alerta","Crítico")))))
B16: =IF($A16="",0,INT(($A16-Macrociclo!$C$11)/7)+1) -> 0 | H16: =IF(COUNT($D16:$G16)<4,0,SUM($D16:$G16)) -> 0 | I16: =IF($H16=0,"",IF($H16<=8,"Ótimo",IF($H16<=12,"Bom",IF($H16<=16,"Regular",IF($H16<=20,"Alerta","Crítico")))))
B17: =IF($A17="",0,INT(($A17-Macrociclo!$C$11)/7)+1) -> 0 | H17: =IF(COUNT($D17:$G17)<4,0,SUM($D17:$G17)) -> 0 | I17: =IF($H17=0,"",IF($H17<=8,"Ótimo",IF($H17<=12,"Bom",IF($H17<=16,"Regular",IF($H17<=20,"Alerta","Crítico")))))
B18: =IF($A18="",0,INT(($A18-Macrociclo!$C$11)/7)+1) -> 0 | H18: =IF(COUNT($D18:$G18)<4,0,SUM($D18:$G18)) -> 0 | I18: =IF($H18=0,"",IF($H18<=8,"Ótimo",IF($H18<=12,"Bom",IF($H18<=16,"Regular",IF($H18<=20,"Alerta","Crítico")))))
B19: =IF($A19="",0,INT(($A19-Macrociclo!$C$11)/7)+1) -> 0 | H19: =IF(COUNT($D19:$G19)<4,0,SUM($D19:$G19)) -> 0 | I19: =IF($H19=0,"",IF($H19<=8,"Ótimo",IF($H19<=12,"Bom",IF($H19<=16,"Regular",IF($H19<=20,"Alerta","Crítico")))))
... B1007: =IF($A1007="",0,INT(($A1007-Macrociclo!$C$11)/7)+1) -> 0 | H1007: =IF(COUNT($D1007:$G1007)<4,0,SUM($D1007:$G1007)) -> 0 | I1007: =IF($H1007=0,"",IF($H1007<=8,"Ótimo",IF($H1007<=12,"Bom",IF($H1007<=16,"Regular",IF($H1007<=20,"Alerta","Crítico")))))

Sheet Presença
A1: CONTROLE DE PRESENÇA
A2: Chamada por sessão à esquerda; percentual de presença por atleta calculado automaticamente à direita.
I5: RESUMO POR ATLETA
A7: Data | B7: Semana | C7: Sessão / Tipo | D7: Atleta | E7: Presença | F7: Min. Participados | G7: Justificativa | I7: Atleta | J7: Registros | K7: Presenças | L7: % Presença | M7: Faltas | N7: Lesão / DM | O7: Min. Totais | P7: Situação
B8: =IF($A8="",0,INT(($A8-Macrociclo!$C$11)/7)+1) -> 0 | I8: =IF(Cadastro!$B7="","",Cadastro!$B7) | J8: =IF($I8="",0,COUNTIFS($D$8:$D$1007,$I8)) -> 0 | K8: =IF($I8="",0,COUNTIFS($D$8:$D$1007,$I8,$E$8:$E$1007,"Presente")) -> 0 | L8: =IF($J8=0,0,$K8/$J8) -> 0 | M8: =IF($I8="",0,COUNTIFS($D$8:$D$1007,$I8,$E$8:$E$1007,"Falta Justificada")+COUNTIFS($D$8:$D$1007,$I8,$E$8:$E$1007,"Falta Não Justificada")) -> 0 | N8: =IF($I8="",0,COUNTIFS($D$8:$D$1007,$I8,$E$8:$E$1007,"Lesionado")+COUNTIFS($D$8:$D$1007,$I8,$E$8:$E$1007,"Departamento Médico")) -> 0 | O8: =IF($I8="",0,SUMIFS($F$8:$F$1007,$D$8:$D$1007,$I8)) -> 0 | P8: =IF($I8="","",IF($J8=0,"Sem registro",IF($L8>=0.9,"Excelente",IF($L8>=0.75,"Regular","Baixa assiduidade"))))
B9: =IF($A9="",0,INT(($A9-Macrociclo!$C$11)/7)+1) -> 0 | I9: =IF(Cadastro!$B8="","",Cadastro!$B8) | J9: =IF($I9="",0,COUNTIFS($D$8:$D$1007,$I9)) -> 0 | K9: =IF($I9="",0,COUNTIFS($D$8:$D$1007,$I9,$E$8:$E$1007,"Presente")) -> 0 | L9: =IF($J9=0,0,$K9/$J9) -> 0 | M9: =IF($I9="",0,COUNTIFS($D$8:$D$1007,$I9,$E$8:$E$1007,"Falta Justificada")+COUNTIFS($D$8:$D$1007,$I9,$E$8:$E$1007,"Falta Não Justificada")) -> 0 | N9: =IF($I9="",0,COUNTIFS($D$8:$D$1007,$I9,$E$8:$E$1007,"Lesionado")+COUNTIFS($D$8:$D$1007,$I9,$E$8:$E$1007,"Departamento Médico")) -> 0 | O9: =IF($I9="",0,SUMIFS($F$8:$F$1007,$D$8:$D$1007,$I9)) -> 0 | P9: =IF($I9="","",IF($J9=0,"Sem registro",IF($L9>=0.9,"Excelente",IF($L9>=0.75,"Regular","Baixa assiduidade"))))
B10: =IF($A10="",0,INT(($A10-Macrociclo!$C$11)/7)+1) -> 0 | I10: =IF(Cadastro!$B9="","",Cadastro!$B9) | J10: =IF($I10="",0,COUNTIFS($D$8:$D$1007,$I10)) -> 0 | K10: =IF($I10="",0,COUNTIFS($D$8:$D$1007,$I10,$E$8:$E$1007,"Presente")) -> 0 | L10: =IF($J10=0,0,$K10/$J10) -> 0 | M10: =IF($I10="",0,COUNTIFS($D$8:$D$1007,$I10,$E$8:$E$1007,"Falta Justificada")+COUNTIFS($D$8:$D$1007,$I10,$E$8:$E$1007,"Falta Não Justificada")) -> 0 | N10: =IF($I10="",0,COUNTIFS($D$8:$D$1007,$I10,$E$8:$E$1007,"Lesionado")+COUNTIFS($D$8:$D$1007,$I10,$E$8:$E$1007,"Departamento Médico")) -> 0 | O10: =IF($I10="",0,SUMIFS($F$8:$F$1007,$D$8:$D$1007,$I10)) -> 0 | P10: =IF($I10="","",IF($J10=0,"Sem registro",IF($L10>=0.9,"Excelente",IF($L10>=0.75,"Regular","Baixa assiduidade"))))
B11: =IF($A11="",0,INT(($A11-Macrociclo!$C$11)/7)+1) -> 0 | I11: =IF(Cadastro!$B10="","",Cadastro!$B10) | J11: =IF($I11="",0,COUNTIFS($D$8:$D$1007,$I11)) -> 0 | K11: =IF($I11="",0,COUNTIFS($D$8:$D$1007,$I11,$E$8:$E$1007,"Presente")) -> 0 | L11: =IF($J11=0,0,$K11/$J11) -> 0 | M11: =IF($I11="",0,COUNTIFS($D$8:$D$1007,$I11,$E$8:$E$1007,"Falta Justificada")+COUNTIFS($D$8:$D$1007,$I11,$E$8:$E$1007,"Falta Não Justificada")) -> 0 | N11: =IF($I11="",0,COUNTIFS($D$8:$D$1007,$I11,$E$8:$E$1007,"Lesionado")+COUNTIFS($D$8:$D$1007,$I11,$E$8:$E$1007,"Departamento Médico")) -> 0 | O11: =IF($I11="",0,SUMIFS($F$8:$F$1007,$D$8:$D$1007,$I11)) -> 0 | P11: =IF($I11="","",IF($J11=0,"Sem registro",IF($L11>=0.9,"Excelente",IF($L11>=0.75,"Regular","Baixa assiduidade"))))
B12: =IF($A12="",0,INT(($A12-Macrociclo!$C$11)/7)+1) -> 0 | I12: =IF(Cadastro!$B11="","",Cadastro!$B11) | J12: =IF($I12="",0,COUNTIFS($D$8:$D$1007,$I12)) -> 0 | K12: =IF($I12="",0,COUNTIFS($D$8:$D$1007,$I12,$E$8:$E$1007,"Presente")) -> 0 | L12: =IF($J12=0,0,$K12/$J12) -> 0 | M12: =IF($I12="",0,COUNTIFS($D$8:$D$1007,$I12,$E$8:$E$1007,"Falta Justificada")+COUNTIFS($D$8:$D$1007,$I12,$E$8:$E$1007,"Falta Não Justificada")) -> 0 | N12: =IF($I12="",0,COUNTIFS($D$8:$D$1007,$I12,$E$8:$E$1007,"Lesionado")+COUNTIFS($D$8:$D$1007,$I12,$E$8:$E$1007,"Departamento Médico")) -> 0 | O12: =IF($I12="",0,SUMIFS($F$8:$F$1007,$D$8:$D$1007,$I12)) -> 0 | P12: =IF($I12="","",IF($J12=0,"Sem registro",IF($L12>=0.9,"Excelente",IF($L12>=0.75,"Regular","Baixa assiduidade"))))
B13: =IF($A13="",0,INT(($A13-Macrociclo!$C$11)/7)+1) -> 0 | I13: =IF(Cadastro!$B12="","",Cadastro!$B12) | J13: =IF($I13="",0,COUNTIFS($D$8:$D$1007,$I13)) -> 0 | K13: =IF($I13="",0,COUNTIFS($D$8:$D$1007,$I13,$E$8:$E$1007,"Presente")) -> 0 | L13: =IF($J13=0,0,$K13/$J13) -> 0 | M13: =IF($I13="",0,COUNTIFS($D$8:$D$1007,$I13,$E$8:$E$1007,"Falta Justificada")+COUNTIFS($D$8:$D$1007,$I13,$E$8:$E$1007,"Falta Não Justificada")) -> 0 | N13: =IF($I13="",0,COUNTIFS($D$8:$D$1007,$I13,$E$8:$E$1007,"Lesionado")+COUNTIFS($D$8:$D$1007,$I13,$E$8:$E$1007,"Departamento Médico")) -> 0 | O13: =IF($I13="",0,SUMIFS($F$8:$F$1007,$D$8:$D$1007,$I13)) -> 0 | P13: =IF($I13="","",IF($J13=0,"Sem registro",IF($L13>=0.9,"Excelente",IF($L13>=0.75,"Regular","Baixa assiduidade"))))
B14: =IF($A14="",0,INT(($A14-Macrociclo!$C$11)/7)+1) -> 0 | I14: =IF(Cadastro!$B13="","",Cadastro!$B13) | J14: =IF($I14="",0,COUNTIFS($D$8:$D$1007,$I14)) -> 0 | K14: =IF($I14="",0,COUNTIFS($D$8:$D$1007,$I14,$E$8:$E$1007,"Presente")) -> 0 | L14: =IF($J14=0,0,$K14/$J14) -> 0 | M14: =IF($I14="",0,COUNTIFS($D$8:$D$1007,$I14,$E$8:$E$1007,"Falta Justificada")+COUNTIFS($D$8:$D$1007,$I14,$E$8:$E$1007,"Falta Não Justificada")) -> 0 | N14: =IF($I14="",0,COUNTIFS($D$8:$D$1007,$I14,$E$8:$E$1007,"Lesionado")+COUNTIFS($D$8:$D$1007,$I14,$E$8:$E$1007,"Departamento Médico")) -> 0 | O14: =IF($I14="",0,SUMIFS($F$8:$F$1007,$D$8:$D$1007,$I14)) -> 0 | P14: =IF($I14="","",IF($J14=0,"Sem registro",IF($L14>=0.9,"Excelente",IF($L14>=0.75,"Regular","Baixa assiduidade"))))
B15: =IF($A15="",0,INT(($A15-Macrociclo!$C$11)/7)+1) -> 0 | I15: =IF(Cadastro!$B14="","",Cadastro!$B14) | J15: =IF($I15="",0,COUNTIFS($D$8:$D$1007,$I15)) -> 0 | K15: =IF($I15="",0,COUNTIFS($D$8:$D$1007,$I15,$E$8:$E$1007,"Presente")) -> 0 | L15: =IF($J15=0,0,$K15/$J15) -> 0 | M15: =IF($I15="",0,COUNTIFS($D$8:$D$1007,$I15,$E$8:$E$1007,"Falta Justificada")+COUNTIFS($D$8:$D$1007,$I15,$E$8:$E$1007,"Falta Não Justificada")) -> 0 | N15: =IF($I15="",0,COUNTIFS($D$8:$D$1007,$I15,$E$8:$E$1007,"Lesionado")+COUNTIFS($D$8:$D$1007,$I15,$E$8:$E$1007,"Departamento Médico")) -> 0 | O15: =IF($I15="",0,SUMIFS($F$8:$F$1007,$D$8:$D$1007,$I15)) -> 0 | P15: =IF($I15="","",IF($J15=0,"Sem registro",IF($L15>=0.9,"Excelente",IF($L15>=0.75,"Regular","Baixa assiduidade"))))
B16: =IF($A16="",0,INT(($A16-Macrociclo!$C$11)/7)+1) -> 0 | I16: =IF(Cadastro!$B15="","",Cadastro!$B15) | J16: =IF($I16="",0,COUNTIFS($D$8:$D$1007,$I16)) -> 0 | K16: =IF($I16="",0,COUNTIFS($D$8:$D$1007,$I16,$E$8:$E$1007,"Presente")) -> 0 | L16: =IF($J16=0,0,$K16/$J16) -> 0 | M16: =IF($I16="",0,COUNTIFS($D$8:$D$1007,$I16,$E$8:$E$1007,"Falta Justificada")+COUNTIFS($D$8:$D$1007,$I16,$E$8:$E$1007,"Falta Não Justificada")) -> 0 | N16: =IF($I16="",0,COUNTIFS($D$8:$D$1007,$I16,$E$8:$E$1007,"Lesionado")+COUNTIFS($D$8:$D$1007,$I16,$E$8:$E$1007,"Departamento Médico")) -> 0 | O16: =IF($I16="",0,SUMIFS($F$8:$F$1007,$D$8:$D$1007,$I16)) -> 0 | P16: =IF($I16="","",IF($J16=0,"Sem registro",IF($L16>=0.9,"Excelente",IF($L16>=0.75,"Regular","Baixa assiduidade"))))
B17: =IF($A17="",0,INT(($A17-Macrociclo!$C$11)/7)+1) -> 0 | I17: =IF(Cadastro!$B16="","",Cadastro!$B16) | J17: =IF($I17="",0,COUNTIFS($D$8:$D$1007,$I17)) -> 0 | K17: =IF($I17="",0,COUNTIFS($D$8:$D$1007,$I17,$E$8:$E$1007,"Presente")) -> 0 | L17: =IF($J17=0,0,$K17/$J17) -> 0 | M17: =IF($I17="",0,COUNTIFS($D$8:$D$1007,$I17,$E$8:$E$1007,"Falta Justificada")+COUNTIFS($D$8:$D$1007,$I17,$E$8:$E$1007,"Falta Não Justificada")) -> 0 | N17: =IF($I17="",0,COUNTIFS($D$8:$D$1007,$I17,$E$8:$E$1007,"Lesionado")+COUNTIFS($D$8:$D$1007,$I17,$E$8:$E$1007,"Departamento Médico")) -> 0 | O17: =IF($I17="",0,SUMIFS($F$8:$F$1007,$D$8:$D$1007,$I17)) -> 0 | P17: =IF($I17="","",IF($J17=0,"Sem registro",IF($L17>=0.9,"Excelente",IF($L17>=0.75,"Regular","Baixa assiduidade"))))
B18: =IF($A18="",0,INT(($A18-Macrociclo!$C$11)/7)+1) -> 0 | I18: =IF(Cadastro!$B17="","",Cadastro!$B17) | J18: =IF($I18="",0,COUNTIFS($D$8:$D$1007,$I18)) -> 0 | K18: =IF($I18="",0,COUNTIFS($D$8:$D$1007,$I18,$E$8:$E$1007,"Presente")) -> 0 | L18: =IF($J18=0,0,$K18/$J18) -> 0 | M18: =IF($I18="",0,COUNTIFS($D$8:$D$1007,$I18,$E$8:$E$1007,"Falta Justificada")+COUNTIFS($D$8:$D$1007,$I18,$E$8:$E$1007,"Falta Não Justificada")) -> 0 | N18: =IF($I18="",0,COUNTIFS($D$8:$D$1007,$I18,$E$8:$E$1007,"Lesionado")+COUNTIFS($D$8:$D$1007,$I18,$E$8:$E$1007,"Departamento Médico")) -> 0 | O18: =IF($I18="",0,SUMIFS($F$8:$F$1007,$D$8:$D$1007,$I18)) -> 0 | P18: =IF($I18="","",IF($J18=0,"Sem registro",IF($L18>=0.9,"Excelente",IF($L18>=0.75,"Regular","Baixa assiduidade"))))
B19: =IF($A19="",0,INT(($A19-Macrociclo!$C$11)/7)+1) -> 0 | I19: =IF(Cadastro!$B18="","",Cadastro!$B18) | J19: =IF($I19="",0,COUNTIFS($D$8:$D$1007,$I19)) -> 0 | K19: =IF($I19="",0,COUNTIFS($D$8:$D$1007,$I19,$E$8:$E$1007,"Presente")) -> 0 | L19: =IF($J19=0,0,$K19/$J19) -> 0 | M19: =IF($I19="",0,COUNTIFS($D$8:$D$1007,$I19,$E$8:$E$1007,"Falta Justificada")+COUNTIFS($D$8:$D$1007,$I19,$E$8:$E$1007,"Falta Não Justificada")) -> 0 | N19: =IF($I19="",0,COUNTIFS($D$8:$D$1007,$I19,$E$8:$E$1007,"Lesionado")+COUNTIFS($D$8:$D$1007,$I19,$E$8:$E$1007,"Departamento Médico")) -> 0 | O19: =IF($I19="",0,SUMIFS($F$8:$F$1007,$D$8:$D$1007,$I19)) -> 0 | P19: =IF($I19="","",IF($J19=0,"Sem registro",IF($L19>=0.9,"Excelente",IF($L19>=0.75,"Regular","Baixa assiduidade"))))
... B67: =IF($A67="",0,INT(($A67-Macrociclo!$C$11)/7)+1) -> 0 | I67: =IF(Cadastro!$B66="","",Cadastro!$B66) | J67: =IF($I67="",0,COUNTIFS($D$8:$D$1007,$I67)) -> 0 | K67: =IF($I67="",0,COUNTIFS($D$8:$D$1007,$I67,$E$8:$E$1007,"Presente")) -> 0 | L67: =IF($J67=0,0,$K67/$J67) -> 0 | M67: =IF($I67="",0,COUNTIFS($D$8:$D$1007,$I67,$E$8:$E$1007,"Falta Justificada")+COUNTIFS($D$8:$D$1007,$I67,$E$8:$E$1007,"Falta Não Justificada")) -> 0 | N67: =IF($I67="",0,COUNTIFS($D$8:$D$1007,$I67,$E$8:$E$1007,"Lesionado")+COUNTIFS($D$8:$D$1007,$I67,$E$8:$E$1007,"Departamento Médico")) -> 0 | O67: =IF($I67="",0,SUMIFS($F$8:$F$1007,$D$8:$D$1007,$I67)) -> 0 | P67: =IF($I67="","",IF($J67=0,"Sem registro",IF($L67>=0.9,"Excelente",IF($L67>=0.75,"Regular","Baixa assiduidade"))))
B68: =IF($A68="",0,INT(($A68-Macrociclo!$C$11)/7)+1) -> 0
B69: =IF($A69="",0,INT(($A69-Macrociclo!$C$11)/7)+1) -> 0
